Workbook
Name Description: Summary!$B$15
Name Div01_General_Requirements: DivisionCostCodeLookup!$F$2:$F$22
Name Div02_Existing_Conditions: DivisionCostCodeLookup!$F$23:$F$36
Name Div03_Concrete: DivisionCostCodeLookup!$F$37:$F$44
Name Div04_Masonry: DivisionCostCodeLookup!$F$45:$F$51
Name Div05_Metals: DivisionCostCodeLookup!$F$52:$F$65
Name Div06_Wood_Plastics_And_Composites: DivisionCostCodeLookup!$F$66:$F$79
Name Div07_Thermaland_Moisture_Protection: DivisionCostCodeLookup!$F$80:$F$104
Name Div08_Openings: DivisionCostCodeLookup!$F$105:$F$125
Name Div09_Finishes: DivisionCostCodeLookup!$F$126:$F$157
Name Div10_Specialties: DivisionCostCodeLookup!$F$158:$F$173
Name Div11_Equipment: DivisionCostCodeLookup!$F$174:$F$182
Name Div12_Furnishings: DivisionCostCodeLookup!$F$183:$F$193
Name Div13_Special_Construction: DivisionCostCodeLookup!$F$194:$F$197
Name Div14_Conveying_Equipment: DivisionCostCodeLookup!$F$198:$F$204
Name Div21_Fire_Suppression: DivisionCostCodeLookup!$F$205:$F$219
Name Div22_Plumbing: DivisionCostCodeLookup!$F$220:$F$236
Name Div23_Heating_Ventilating_And_Air_Conditioning: DivisionCostCodeLookup!$F$237:$F$278
Name Div26_Electrical: DivisionCostCodeLookup!$F$279:$F$308
Name Div27_Communications: DivisionCostCodeLookup!$F$309:$F$328
Name Div28_Electronic_Safety_And_Security: DivisionCostCodeLookup!$F$329:$F$339
Name Div31_Earthwork: DivisionCostCodeLookup!$F$340:$F$353
Name Div32_Exterior_Improvements: DivisionCostCodeLookup!$F$354:$F$383
Name Div33_Utilities: DivisionCostCodeLookup!$F$384:$F$391
Name Div34_Transportation: DivisionCostCodeLookup!$F$392:$F$409
Name Div35_Waterway_And_Marine: DivisionCostCodeLookup!$F$410:$F$423
Name Div41_Material_Proc_And_Handling_Eq.: DivisionCostCodeLookup!$F$424:$F$426
Name Div51_Earthwork_FAA: DivisionCostCodeLookup!$F$428:$F$438
Name Div52_Flexible_Base_Courses_FAA: DivisionCostCodeLookup!$F$439:$F$447
Name Div53_Rigid_Base_Courses_FAA: DivisionCostCodeLookup!$F$448:$F$452
Name Div54_Flexible_Surface_Courses_FAA: DivisionCostCodeLookup!$F$453:$F$457
Name Div55_Rigid_Pavement_FAA: DivisionCostCodeLookup!$F$458:$F$460
Name Div56_Miscellaneous_FAA: DivisionCostCodeLookup!$F$461:$F$474
Name Div57_Fencing_FAA: DivisionCostCodeLookup!$F$475:$F$480
Name Div58_Drainage_FAA: DivisionCostCodeLookup!$F$481:$F$488
Name Div59_Turfing_FAA: DivisionCostCodeLookup!$F$489:$F$496
Name Div60_Lighting_Installation_FAA: DivisionCostCodeLookup!$F$497:$F$507
Name DivisionDescription: DivisionCostCodeLookup!$A$2:$A$37
Name DivisionSummaryList: DivisionCostCodeLookup!$L$2:$L$12
Name EstimateTotal: Summary!$C$34
Name HardCostSubTotal: Summary!$C$21
Name HCostForm: 'Hard Cost Estimate Form'!$H$5
Name projectStage: Summary!$B$12
Name RevNotes: Summary!$B$19
Name Scope: Summary!$B$17
Name ScopeAccuracy: 'Scope and Risk'!$C$3:$C$5
Name SCostForm: 'Optional - Sch & Resource Form'!$G$5
Name SCostForm: 'Soft Cost Estimating Form'!$L$5
Name SoftCostSubtotal: Summary!$C$23
Name SoftCostUoM: SoftCostUom!$G$2:$G$7
Name SoftCostUoM: SoftCostUom!$G$2:$G$8
Name UoM: SoftCostUom!$C$2:$C$15
Name UoM: UoM!$C$2:$C$16

Sheet Summary
B2: =IF(B12<>"", B12, "Estimate Summary") -> Estimate Summary
C3: : Project Title
C4: : Project Number
C5: : Originator
C6: : Project Manager (If Assigned)
C7: : Reviewer/Approver
C8: : Date (Last Revised)
C9: : Revision#
C10: : Scope Accuracy
C11: : Engineering Effort
C12: : Project Stage
B14: SCOPE DESCRIPTION:
B16: SCOPE ASSUMPTIONS AND CLARIFICATIONS:
B18: REVISION NOTES:
B21: HARD COST SUBTOTAL | C21: =HCostForm -> 0
B23: SOFT COST SUBTOTAL | C23: =SCostForm -> 0
B25: HARD COST CONTINGENCY | C25: =C26*C21 -> 0
B26: (Enter % of Hard Cost):
B28: SOFT COST CONTINGENCY | C28: =C29*C23 -> 0
B29: (Enter % of Soft Cost):
B31: ESCALATION | C31: =IFERROR((C21+C23+C25+C28)*C135,0) -> 0
B32: Based on Calculations Below Under "Escalation Calculator" : | C32: =C135
B34: TOTAL PROJECT ESTIMATE | C34: =C21+C23+C25+C28+C31 -> 0
B36: Hard Cost Summary
B37: HARD COST DESCRIPTION | C37: TOTAL
B38: 01 General Requirements | C38: =SUMIF('Hard Cost Estimate Form'!$A$8:$A$1000,B38,'Hard Cost Estimate Form'!$H$8:$H$1000) -> 0
B39: 02 Existing Conditions | C39: =SUMIF('Hard Cost Estimate Form'!$A$8:$A$1000,B39,'Hard Cost Estimate Form'!$H$8:$H$1000) -> 0
B40: 03 Concrete | C40: =SUMIF('Hard Cost Estimate Form'!$A$8:$A$1000,B40,'Hard Cost Estimate Form'!$H$8:$H$1000) -> 0
B41: 04 Masonry | C41: =SUMIF('Hard Cost Estimate Form'!$A$8:$A$1000,B41,'Hard Cost Estimate Form'!$H$8:$H$1000) -> 0
B42: 05 Metals | C42: =SUMIF('Hard Cost Estimate Form'!$A$8:$A$1000,B42,'Hard Cost Estimate Form'!$H$8:$H$1000) -> 0
B43: 06 Wood Plastics And Composites | C43: =SUMIF('Hard Cost Estimate Form'!$A$8:$A$1000,B43,'Hard Cost Estimate Form'!$H$8:$H$1000) -> 0
B44: 07 Thermaland Moisture Protection | C44: =SUMIF('Hard Cost Estimate Form'!$A$8:$A$1000,B44,'Hard Cost Estimate Form'!$H$8:$H$1000) -> 0
B45: 08 Openings | C45: =SUMIF('Hard Cost Estimate Form'!$A$8:$A$1000,B45,'Hard Cost Estimate Form'!$H$8:$H$1000) -> 0
B46: 09 Finishes | C46: =SUMIF('Hard Cost Estimate Form'!$A$8:$A$1000,B46,'Hard Cost Estimate Form'!$H$8:$H$1000) -> 0
B47: 10 Specialties | C47: =SUMIF('Hard Cost Estimate Form'!$A$8:$A$1000,B47,'Hard Cost Estimate Form'!$H$8:$H$1000) -> 0
B48: 11 Equipment | C48: =SUMIF('Hard Cost Estimate Form'!$A$8:$A$1000,B48,'Hard Cost Estimate Form'!$H$8:$H$1000) -> 0
B49: 12 Furnishings | C49: =SUMIF('Hard Cost Estimate Form'!$A$8:$A$1000,B49,'Hard Cost Estimate Form'!$H$8:$H$1000) -> 0
... B73: 60 Lighting Installation FAA | C73: =SUMIF('Hard Cost Estimate Form'!$A$8:$A$1000,B73,'Hard Cost Estimate Form'!$H$8:$H$1000) -> 0
B74: Misc - Not Listed | C74: =SUM('Hard Cost Estimate Form'!$H$8:$H$1000)-SUM(C38:C73) -> 0
B75: 1 | C75: 1
...

Sheet Hard Cost Estimate Form
A1: Hard Cost Estimating Form (Details)
A2: Project Title: | B2: =IF(Summary!B3<>"",Summary!B3,"") | D2: Instructions:
A3: Project #: | B3: =IF(Summary!B4<>"",Summary!B4,"") | D3: Step 1: Select Division from Dropdown in Column A to Populate Options in Column B
A4: Rev #: | B4: =IF(Summary!B9<>"",Summary!B9,"") | D4: Step 2: Select Associated Cost Code Description from Dropdown in Column B [Optional]
A5: Rev # Date: | B5: =IF(Summary!B8<>"",Summary!B8,"") | D5: Step 3: Fill in Estimating Table in Columns (D to G) | G5: Hard Cost Total: | H5: =SUM(H8:H1048576) -> 0
A7: Division | B7: Cost Code Description | C7: Cost Code | D7: Item Description | E7: QTY | F7: Unit | G7: Unit Rate | H7: Total
C8: =IF(A8<>"",IFERROR(VLOOKUP(B8,DivisionCostCodeLookup!$F$2:$G$426,2,FALSE),INT(LEFT(A8,2))&"0000"),"") | H8: =IF(E8*G8<>0,E8*G8,"")
C9: =IF(A9<>"",IFERROR(VLOOKUP(B9,DivisionCostCodeLookup!$F$2:$G$426,2,FALSE),INT(LEFT(A9,2))&"0000"),"") | H9: =IF(E9*G9<>0,E9*G9,"")
C10: =IF(A10<>"",IFERROR(VLOOKUP(B10,DivisionCostCodeLookup!$F$2:$G$426,2,FALSE),INT(LEFT(A10,2))&"0000"),"") | H10: =IF(E10*G10<>0,E10*G10,"")
C11: =IF(A11<>"",IFERROR(VLOOKUP(B11,DivisionCostCodeLookup!$F$2:$G$426,2,FALSE),INT(LEFT(A11,2))&"0000"),"") | H11: =IF(E11*G11<>0,E11*G11,"")
C12: =IF(A12<>"",IFERROR(VLOOKUP(B12,DivisionCostCodeLookup!$F$2:$G$426,2,FALSE),INT(LEFT(A12,2))&"0000"),"") | H12: =IF(E12*G12<>0,E12*G12,"")
C13: =IF(A13<>"",IFERROR(VLOOKUP(B13,DivisionCostCodeLookup!$F$2:$G$426,2,FALSE),INT(LEFT(A13,2))&"0000"),"") | H13: =IF(E13*G13<>0,E13*G13,"")
C14: =IF(A14<>"",IFERROR(VLOOKUP(B14,DivisionCostCodeLookup!$F$2:$G$426,2,FALSE),INT(LEFT(A14,2))&"0000"),"") | H14: =IF(E14*G14<>0,E14*G14,"")
C15: =IF(A15<>"",IFERROR(VLOOKUP(B15,DivisionCostCodeLookup!$F$2:$G$426,2,FALSE),INT(LEFT(A15,2))&"0000"),"") | H15: =IF(E15*G15<>0,E15*G15,"")
C16: =IF(A16<>"",IFERROR(VLOOKUP(B16,DivisionCostCodeLookup!$F$2:$G$426,2,FALSE),INT(LEFT(A16,2))&"0000"),"") | H16: =IF(E16*G16<>0,E16*G16,"")
C17: =IF(A17<>"",IFERROR(VLOOKUP(B17,DivisionCostCodeLookup!$F$2:$G$426,2,FALSE),INT(LEFT(A17,2))&"0000"),"") | H17: =IF(E17*G17<>0,E17*G17,"")
C18: =IF(A18<>"",IFERROR(VLOOKUP(B18,DivisionCostCodeLookup!$F$2:$G$426,2,FALSE),INT(LEFT(A18,2))&"0000"),"") | H18: =IF(E18*G18<>0,E18*G18,"")
C19: =IF(A19<>"",IFERROR(VLOOKUP(B19,DivisionCostCodeLookup!$F$2:$G$426,2,FALSE),INT(LEFT(A19,2))&"0000"),"") | H19: =IF(E19*G19<>0,E19*G19,"")
... C74: =IF(A74<>"",IFERROR(VLOOKUP(B74,DivisionCostCodeLookup!$F$2:$G$426,2,FALSE),INT(LEFT(A74,2))&"0000"),"") | H74: =IF(E74*G74<>0,E74*G74,"")
A75: 02 Existing Conditions | B75: AsbestosAbatement | C75: =IF(A75<>"",IFERROR(VLOOKUP(B75,DivisionCostCodeLookup!$F$2:$G$426,2,FALSE),INT(LEFT(A75,2))&"0000"),"") -> 28213 | H75: =IF(E75*G75<>0,E75*G75,"")
C76: =IF(A76<>"",IFERROR(VLOOKUP(B76,DivisionCostCodeLookup!$F$2:$G$426,2,FALSE),INT(LEFT(A76,2))&"0000"),"") | H76: =IF(E76*G76<>0,E76*G76,"")
C77: =IF(A77<>"",IFERROR(VLOOKUP(B77,DivisionCostCodeLookup!$F$2:$G$426,2,FALSE),INT(LEFT(A77,2))&"0000"),"") | H77: =IF(E77*G77<>0,E77*G77,"")
C78: =IF(A78<>"",IFERROR(VLOOKUP(B78,DivisionCostCodeLookup!$F$2:$G$426,2,FALSE),INT(LEFT(A78,2))&"0000"),"") | H78: =IF(E78*G78<>0,E78*G78,"")
C79: =IF(A79<>"",IFERROR(VLOOKUP(B79,DivisionCostCodeLookup!$F$2:$G$426,2,FALSE),INT(LEFT(A79,2))&"0000"),"") | H79: =IF(E79*G79<>0,E79*G79,"")
C80: =IF(A80<>"",IFERROR(VLOOKUP(B80,DivisionCostCodeLookup!$F$2:$G$426,2,FALSE),INT(LEFT(A80,2))&"0000"),"") | H80: =IF(E80*G80<>0,E80*G80,"")
C81: =IF(A81<>"",IFERROR(VLOOKUP(B81,DivisionCostCodeLookup!$F$2:$G$426,2,FALSE),INT(LEFT(A81,2))&"0000"),"") | H81: =IF(E81*G81<>0,E81*G81,"")
C82: =IF(A82<>"",IFERROR(VLOOKUP(B82,DivisionCostCodeLookup!$F$2:$G$426,2,FALSE),INT(LEFT(A82,2))&"0000"),"") | H82: =IF(E82*G82<>0,E82*G82,"")
C83: =IF(A83<>"",IFERROR(VLOOKUP(B83,DivisionCostCodeLookup!$F$2:$G$426,2,FALSE),INT(LEFT(A83,2))&"0000"),"") | H83: =IF(E83*G83<>0,E83*G83,"")
C84: =IF(A84<>"",IFERROR(VLOOKUP(B84,DivisionCostCodeLookup!$F$2:$G$426,2,FALSE),INT(LEFT(A84,2))&"0000"),"") | H84: =IF(E84*G84<>0,E84*G84,"")
C85: =IF(A85<>"",IFERROR(VLOOKUP(B85,DivisionCostCodeLookup!$F$2:$G$426,2,FALSE),INT(LEFT(A85,2))&"0000"),"") | H85: =IF(E85*G85<>0,E85*G85,"")
C86: =IF(A86<>"",IFERROR(VLOOKUP(B86,DivisionCostCodeLookup!$F$2:$G$426,2,FALSE),INT(LEFT(A86,2))&"0000"),"") | H86: =IF(E86*G86<>0,E86*G86,"")
C87: =IF(A87<>"",IFERROR(VLOOKUP(B87,DivisionCostCodeLookup!$F$2:$G$426,2,FALSE),INT(LEFT(A87,2))&"0000"),"") | H87: =IF(E87*G87<>0,E87*G87,"")
... C1000: =IF(A1000<>"",IFERROR(VLOOKUP(B1000,DivisionCostCodeLookup!$F$2:$G$426,2,FALSE),INT(LEFT(A1000,2))&"0000"),"") | H1000: =IF(E1000*G1000<>0,E1000*G1000,"")

Sheet Soft Cost Estimating Form
A1: Soft Cost Estimating Form (Details) | AA1: =SUM(J8,J12,J13,J14,J15,J16,J17,J18,J21,J22,J24,J25,J26,J28,J29,J31,J32,J33,J34,J36)-'Optional - Sch & Resource Form'!C89 -> 0
B2: Project Title: | D2: =IF(Summary!B3<>"",Summary!B3,"")
B3: Project #: | D3: =IF(Summary!B4<>"",Summary!B4,"") | K3: Estimating Method | L3: Percentage Based
B4: Rev #: | D4: =IF(Summary!B9<>"",Summary!B9,"") | K4: Soft Cost %
B5: Rev # Date: | D5: =IF(Summary!B8<>"",Summary!B8,"") | K5: Soft Cost Total: | L5: =IF(L3="Percentage Based",L4*HardCostSubTotal,SUM(L8:L1048576)) -> 0
A7: Chart Type | B7: Chart Name | C7: Description | D7: Cost Code | E7: Description | F7: Container | G7: Container Description | H7: Interdepartmental Labor | I7: Total Unit Rate | J7: Qty | K7: Unit | L7: Total
A8: M01 | B8: Engineering Standard | C8: =B8 & " - " & LEFT(E8,FIND("-",E8)-1) -> Engineering Standard - Project Admin & Mgmt | D8: 101000 | E8: Project Admin & Mgmt-General | F8: M02 | G8: General Administration | H8: LBR | I8: 186 | J8: ='Optional - Sch & Resource Form'!C17 -> 0 | K8: Hr | L8: =I8*J8 -> 0
A9: M01 | B9: Engineering Standard | C9: =B9 & " - " & LEFT(E9,FIND("-",E9)-1) -> Engineering Standard - Project Admin & Mgmt | D9: 101400 | E9: Project Admin & Mgmt-Design | F9: M02 | G9: General Administration | H9: LBR | I9: 186 | L9: =I9*J9 -> 0
A10: M01 | B10: Engineering Standard | C10: =B10 & " - " & LEFT(E10,FIND("-",E10)-1) -> Engineering Standard - Project Admin & Mgmt | D10: 101500 | E10: Project Admin & Mgmt-Construction | F10: M02 | G10: General Administration | H10: LBR | I10: 186 | L10: =I10*J10 -> 0
A11: M01 | B11: Engineering Standard | C11: =B11 & " - " & LEFT(E11,FIND("-",E11)-1) -> Engineering Standard - Design | D11: 141010 | E11: Design-Outside Design Services | F11: M03 | G11: Design | L11: =I11*J11 -> 0
A12: M01 | B12: Engineering Standard | C12: =B12 & " - " & LEFT(E12,FIND("-",E12)-1) -> Engineering Standard - Design | D12: 141100 | E12: Design-Specification Development | F12: M03 | G12: Design | H12: LBR | I12: 158 | J12: ='Optional - Sch & Resource Form'!C20 -> 0 | K12: Hr | L12: =I12*J12 -> 0
A13: M01 | B13: Engineering Standard | C13: =B13 & " - " & LEFT(E13,FIND("-",E13)-1) -> Engineering Standard - Design | D13: 141600 | E13: Design-Environmental | F13: M03 | G13: Design | H13: LBR | I13: 126 | J13: ='Optional - Sch & Resource Form'!C23 -> 0 | K13: Hr | L13: =I13*J13 -> 0
A14: M01 | B14: Engineering Standard | C14: =B14 & " - " & LEFT(E14,FIND("-",E14)-1) -> Engineering Standard - Design | D14: 141700 | E14: Design-PE Design | F14: M03 | G14: Design | H14: LBR | I14: 158 | J14: ='Optional - Sch & Resource Form'!C28 -> 0 | K14: Hr | L14: =I14*J14 -> 0
A15: M01 | B15: Engineering Standard | C15: =B15 & " - " & LEFT(E15,FIND("-",E15)-1) -> Engineering Standard - Design | D15: 141800 | E15: Design-Survey | F15: M03 | G15: Design | H15: LBR | I15: 158 | J15: ='Optional - Sch & Resource Form'!C32 -> 0 | K15: Hr | L15: =I15*J15 -> 0
A16: M01 | B16: Engineering Standard | C16: =B16 & " - " & LEFT(E16,FIND("-",E16)-1) -> Engineering Standard - Design | D16: 141900 | E16: Design-Drawing and Development | F16: M03 | G16: Design | H16: LBR | I16: 158 | J16: ='Optional - Sch & Resource Form'!C37 -> 0 | K16: Hr | L16: =I16*J16 -> 0
A17: M01 | B17: Engineering Standard | C17: =B17 & " - " & LEFT(E17,FIND("-",E17)-1) -> Engineering Standard - Design | D17: 142100 | E17: Design-Construction/Inspection Suppor | F17: M03 | G17: Design | H17: LBR | I17: 147 | J17: ='Optional - Sch & Resource Form'!C41 -> 0 | K17: Hr | L17: =I17*J17 -> 0
A18: M01 | B18: Engineering Standard | C18: =B18 & " - " & LEFT(E18,FIND("-",E18)-1) -> Engineering Standard - Design | D18: 142600 | E18: Design-IT Design Support | F18: M03 | G18: Design | H18: LBR | I18: 145 | J18: ='Optional - Sch & Resource Form'!C44 -> 0 | K18: Hr | L18: =I18*J18 -> 0
A19: M01 | B19: Engineering Standard | C19: =B19 & " - " & LEFT(E19,FIND("-",E19)-1) -> Engineering Standard - Development | D19: 171500 | E19: Development-Conceptual Design | F19: M03 | G19: Design | H19: LBR | L19: =I19*J19 -> 0
A20: M01 | B20: Engineering Standard | C20: =B20 & " - " & LEFT(E20,FIND("-",E20)-1) -> Engineering Standard - Construction | D20: 191100 | E20: Construction-Equipment Contracts | F20: M04 | G20: Execute/Build | H20: LBR | L20: =I20*J20 -> 0
A21: M01 | B21: Engineering Standard | C21: =B21 & " - " & LEFT(E21,FIND("-",E21)-1) -> Engineering Standard - Construction | D21: 191200 | E21: Construction-Management | F21: M04 | G21: Execute/Build | H21: LBR | I21: 170 | J21: ='Optional - Sch & Resource Form'!C47 -> 0 | K21: Hr | L21: =I21*J21 -> 0
A22: M01 | B22: Engineering Standard | C22: =B22 & " - " & LEFT(E22,FIND("-",E22)-1) -> Engineering Standard - Construction | D22: 191300 | E22: Construction-Inspection | F22: M04 | G22: Execute/Build | H22: LBR | I22: 147 | J22: ='Optional - Sch & Resource Form'!C52 -> 0 | K22: Hr | L22: =I22*J22 -> 0
A23: M01 | B23: Engineering Standard | C23: =B23 & " - " & LEFT(E23,FIND("-",E23)-1) -> Engineering Standard - Construction | D23: 191400 | E23: Construction-Testing | F23: M04 | G23: Execute/Build | H23: LBR | L23: =I23*J23 -> 0
A24: M01 | B24: Engineering Standard | C24: =B24 & " - " & LEFT(E24,FIND("-",E24)-1) -> Engineering Standard - Construction | D24: 191500 | E24: Construction-Survey | F24: M04 | G24: Execute/Build | H24: LBR | I24: 158 | J24: ='Optional - Sch & Resource Form'!C56 -> 0 | K24: Hr | L24: =I24*J24 -> 0
A25: M01 | B25: Engineering Standard | C25: =B25 & " - " & LEFT(E25,FIND("-",E25)-1) -> Engineering Standard - Construction | D25: 191600 | E25: Construction-Environmental | F25: M04 | G25: Execute/Build | H25: LBR | I25: 132 | J25: ='Optional - Sch & Resource Form'!C59 -> 0 | K25: Hr | L25: =I25*J25 -> 0
A26: M01 | B26: Engineering Standard | C26: =B26 & " - " & LEFT(E26,FIND("-",E26)-1) -> Engineering Standard - Construction | D26: 191800 | E26: Construction-Engineering Support | F26: M04 | G26: Execute/Build | H26: LBR | I26: 158 | J26: ='Optional - Sch & Resource Form'!C64 -> 0 | K26: Hr | L26: =I26*J26 -> 0
A27: M01 | B27: Engineering Standard | C27: =B27 & " - " & LEFT(E27,FIND("-",E27)-1) -> Engineering Standard - Construction | D27: 191810 | E27: Construction-Outside Construction Services | F27: M04 | G27: Execute/Build | L27: =I27*J27 -> 0
A28: M01 | B28: Engineering Standard | C28: =B28 & " - " & LEFT(E28,FIND("-",E28)-1) -> Engineering Standard - Construction | D28: 191900 | E28: Construction-Maintenance | F28: M04 | G28: Execute/Build | H28: LBR | I28: 147 | J28: ='Optional - Sch & Resource Form'!C67 -> 0 | K28: Hr | L28: =I28*J28 -> 0
A29: M01 | B29: Engineering Standard | C29: =B29 & " - " & LEFT(E29,FIND("-",E29)-1) -> Engineering Standard - Construction | D29: 192000 | E29: Construction-IT | F29: M04 | G29: Execute/Build | H29: LBR | I29: 145 | J29: ='Optional - Sch & Resource Form'!C70 -> 0 | K29: Hr | L29: =I29*J29 -> 0
A30: M01 | B30: Engineering Standard | C30: =B30 & " - " & LEFT(E30,FIND("-",E30)-1) -> Engineering Standard - Permitting | D30: 201400 | E30: Permitting-City | F30: M02 | G30: General Administration | H30: LBR | L30: =I30*J30 -> 0
A31: M01 | B31: Engineering Standard | C31: =B31 & " - " & LEFT(E31,FIND("-",E31)-1) -> Engineering Standard - Project Close Out | D31: 781100 | E31: Project Close Out-As Builts | F31: M05 | G31: Close-out | H31: LBR | I31: 141 | J31: ='Optional - Sch & Resource Form'!C75 -> 0 | K31: Hr | L31: =I31*J31 -> 0
A32: M01 | B32: Engineering Standard | C32: =B32 & " - " & LEFT(E32,FIND("-",E32)-1) -> Engineering Standard - Project Close Out | D32: 781200 | E32: Project Close Out-Survey | F32: M05 | G32: Close-out | H32: LBR | I32: 158 | J32: ='Optional - Sch & Resource Form'!C78 -> 0 | K32: Hr | L32: =I32*J32 -> 0
A33: M01 | B33: Engineering Standard | C33: =B33 & " - " & LEFT(E33,FIND("-",E33)-1) -> Engineering Standard - Project Close Out | D33: 781300 | E33: Project Close Out-Technical Reference Center | F33: M05 | G33: Close-out | H33: LBR | I33: 141 | J33: ='Optional - Sch & Resource Form'!C81 -> 0 | K33: Hr | L33: =I33*J33 -> 0
A34: M01 | B34: Engineering Standard | C34: =B34 & " - " & LEFT(E34,FIND("-",E34)-1) -> Engineering Standard - Project Close Out | D34: 781400 | E34: Project Close Out-Geographic Information System | F34: M05 | G34: Close-out | H34: LBR | I34: 141 | J34: ='Optional - Sch & Resource Form'!C84 -> 0 | K34: Hr | L34: =I34*J34 -> 0
A35: M01 | B35: Engineering Standard | C35: =B35 & " - " & LEFT(E35,FIND("-",E35)-1) -> Engineering Standard - Capitalized Alloc Sup Svs | D35: 908550 | E35: Capitalized Alloc Sup Svs-Annual Engineering Adjustment | F35: M02 | G35: General Administration | I35: 63 | L35: =I35*J35 -> 0
A36: M01 | B36: Engineering Standard | C36: =B36 & " - " & LEFT(E36,FIND("-",E36)-1) -> Engineering Standard - Capitalized Alloc Sup Svs | D36: 909000 | E36: Capitalized Alloc Sup Svs-Capitalized Allocated Supp Svs | F36: M02 | G36: General Administration | I36: 63 | J36: ='Optional - Sch & Resource Form'!C87 -> 0 | K36: Hr | L36: =I36*J36 -> 0
A37: M02 | B37: IT Standard | C37: =B37 & " - " & LEFT(E37,FIND("-",E37)-1) -> IT Standard - Project Admin & Mgmt | D37: 101000 | E37: Project Admin & Mgmt-General | F37: M02 | G37: General Administration | H37: LBR | I37: 162 | K37: Hr | L37: =I37*J37 -> 0
A38: M02 | B38: IT Standard | C38: =B38 & " - " & LEFT(E38,FIND("-",E38)-1) -> IT Standard - Project Admin & Mgmt | D38: 101200 | E38: Project Admin & Mgmt-Project Mgmt | F38: M02 | G38: General Administration | H38: LBR | I38: 162 | K38: Hr | L38: =I38*J38 -> 0
A39: M02 | B39: IT Standard | C39: =B39 & " - " & LEFT(E39,FIND("-",E39)-1) -> IT Standard - Analysis & Requirements Defin. | D39: 121000 | E39: Analysis & Requirements Defin.-General | F39: M01 | G39: Project Planning | H39: LBR | I39: 149 | K39: Hr | L39: =I39*J39 -> 0
A40: M02 | B40: IT Standard | C40: =B40 & " - " & LEFT(E40,FIND("-",E40)-1) -> IT Standard - Analysis & Requirements Defin. | D40: 121200 | E40: Analysis & Requirements Defin.-Select Vendor | F40: M01 | G40: Project Planning | H40: LBR | I40: 149 | K40: Hr | L40: =I40*J40 -> 0
A41: M02 | B41: IT Standard | C41: =B41 & " - " & LEFT(E41,FIND("-",E41)-1) -> IT Standard - Security | D41: 131000 | E41: Security-General | F41: M02 | G41: General Administration | H41: LBR | I41: 149 | K41: Hr | L41: =I41*J41 -> 0
...

Sheet Optional - Sch & Resource Form
A1: Schedule & Resource Estimate Form
A2: Project Title: | B2: =IF(Summary!B3<>"",Summary!B3,"")
A3: Project #: | B3: =IF(Summary!B4<>"",Summary!B4,"")
A4: Rev #: | B4: =IF(Summary!B9<>"",Summary!B9,"")
A5: Rev # Date: | B5: =IF(Summary!B8<>"",Summary!B8,"")
A7: Estimated Schedule
A8: Phase | B8: Start Date | C8: End Date | D8: Duration (Wks)
A9: Project Administration | D9: =IFERROR(DATEDIF(B9,C9,"d")/7,0) -> 0
A10: Design | D10: =IFERROR(DATEDIF(B10,C10,"d")/7,0) -> 0
A11: Execute/Build | D11: =IFERROR(DATEDIF(B11,C11,"d")/7,0) -> 0
A12: Close-Out | D12: =IFERROR(DATEDIF(B12,C12,"d")/7,0) -> 0
A14: Estimated Resources
A15: Role | B15: Avg. Hrs/Wk | C15: Total Hours
A16: Project Manager | C16: =B16*SUM($D$9:$D$12) -> 0
B17: TOTAL | C17: =C16 -> 0 | D17: 101000 - Project Admin & Mgmt-General
A19: Spec Writer | C19: =B19*$D$10 -> 0
B20: TOTAL | C20: =C19 -> 0 | D20: 141100 - Design-Specification Development
A22: Environmental Planner | C22: =B22*D10 -> 0
B23: TOTAL | C23: =C22 -> 0 | D23: 141600 - Design-Environmental
A25: Project Engineer | C25: =B25*$D$10 -> 0
A26: Electrical Engineer | C26: =B26*$D$10 -> 0
A27: Facility Engineer | C27: =B27*$D$10 -> 0
B28: TOTAL | C28: =SUM(C25:C27) -> 0 | D28: 141700 - Design-PE Design
A30: Surveyor | C30: =B30*$D$10 -> 0
A31: Locates | C31: =B31*$D$10 -> 0
B32: TOTAL | C32: =SUM(C30:C31) -> 0 | D32: 141800 - Design-Survey
A34: CAD Tech | C34: =B34*$D$10 -> 0
A35: BIM Tech | C35: =B35*$D$10 -> 0
A36: TRC Tech | C36: =B36*$D$10 -> 0
B37: TOTAL | C37: =SUM(C34:C36) -> 0 | D37: 141900 - Design-Drawing and Development
A39: Construction Manager | C39: =B39*$D$10 -> 0
A40: Inspector | C40: =B40*$D$10 -> 0
B41: TOTAL | C41: =SUM(C39:C40) -> 0 | D41: 142100 - Design-Construction/Inspection Support
A43: IT Resource | C43: =B43*$D$10 -> 0
B44: TOTAL | C44: =C43 -> 0 | D44: 142600 - Design-IT Design Support
A46: Construction Manager | C46: =B46*$D$11 -> 0
B47: TOTAL | C47: =C46 -> 0 | D47: 191200 - Construction-Management
A49: Civil Inspector | C49: =B49*$D$11 -> 0
A50: Electrical Inspector | C50: =B50*$D$11 -> 0
A51: Mechanical Inspector | C51: =B51*$D$11 -> 0
...

Sheet Dashboard
B3: ESTIMATE DASHBOARD
B6: Project Title: | E6: =IF(Summary!B3<>"",Summary!B3,"")
B7: Project #: | E7: =IF(Summary!B4<>"",Summary!B4,"")
B8: Rev # | E8: =IF(Summary!B9<>"",Summary!B9,"")
B9: Rev # Date | E9: =IF(Summary!B8<>"",Summary!B8,"")
B12: Project Estimate Chart
B36: Chart is auto-populated from 'Project Estimate' table below
B38: Project Estimate
B39: Risk = Contingency + Escalation | I39: Performance Metric
D40: Hard ($) | E40: Soft ($) | F40: Contingency ($) | G40: Escalation ($) | H40: Estimate ($) | I40: Low Range ($) | J40: High Range ($)
B41: Project Charter
B42: Business Case - Gate 1
B43: Preliminary Design - Gate 2
B44: 100% Design/ Pre-Bid - Gate 3
B45: Bid Acceptance - Gate 4
B46: Project Closeout - Gate 5

Sheet DivisionCostCodeLookup
A1: Division | B1: CostCode | C1: Division Number | D1: DivisionLookup | F1: Description | G1: CostCode | H1: Division Number | I1: CostCodeSeg 2 | J1: CostCodeSeg 3 | L1: Description | M1: Costcode | P1: SUBGROUP: GENERAL REQUIREMENTS
A2: 01 General Requirements | B2: 10000 | C2: 1 | D2: Division01 | G2: 10000 | H2: 1 | I2: 00 | J2: 00 | L2: PROJECT MANAGEMENT | M2: 100000 | P2: Division 01 - General Requirements
A3: 02 Existing Conditions | B3: 20000 | C3: 2 | D3: Division02 | F3: Contractor'sManagementandCoordination | G3: 13100 | H3: 1 | I3: 31 | J3: 00 | L3: DESIGN | M3: 140000 | P3: 13100 | Q3: Contractor's Management and Coordination
A4: 03 Concrete | B4: 30000 | C4: 3 | D4: Division03 | F4: SubmittalProcedures | G4: 13300 | H4: 1 | I4: 33 | J4: 0 | L4: DEVELOPMENT | M4: 170000 | P4: 13300 | Q4: Submittal Procedures
A5: 04 Masonry | B5: 40000 | C5: 4 | D5: Division04 | F5: SecurityControl | G5: 13500 | H5: 1 | I5: 35 | J5: 0 | L5: CONSTRUCTION | M5: 190000 | P5: 13500 | Q5: Security Control
A6: 05 Metals | B6: 50000 | C6: 5 | D6: Division05 | F6: Escort | G6: 13501 | H6: 1 | I6: 35 | J6: 1 | L6: PERMITTING | M6: 200000 | P6: 13501 | Q6: Escort
A7: 06 Wood Plastics And Composites | B7: 60000 | C7: 6 | D7: Division06 | F7: Permits | G7: 14100 | H7: 1 | I7: 14 | J7: 0 | P7: 14100 | Q7: Permits
A8: 07 Thermaland Moisture Protection | B8: 70000 | C8: 7 | D8: Division07 | F8: MobilizationandDemobilization | G8: 15000 | H8: 1 | I8: 50 | J8: 00 | L8: PROJECT CLOSE-OUT | M8: 780000 | P8: 15000 | Q8: Mobilization and Demobilization
A9: 08 Openings | B9: 80000 | C9: 8 | D9: Division08 | F9: TrafficControl | G9: 15001 | H9: 1 | I9: 50 | J9: 1 | L9: CONTINGENCY | M9: 790000 | P9: 15001 | Q9: Traffic Control
A10: 09 Finishes | B10: 90000 | C10: 9 | D10: Division09 | F10: Sweeping | G10: 15002 | H10: 1 | I10: 50 | J10: 2 | L10: CASS | M10: 909000 | P10: 15002 | Q10: Sweeping
A11: 10 Specialties | B11: 100000 | C11: 10 | D11: Division10 | F11: TemporaryHeating,CoolingandVentilating | G11: 15123 | H11: 1 | I11: 51 | J11: 23 | L11: CONVERSION | M11: 0 | P11: 15123 | Q11: Temporary Heating, Cooling and Ventilating
A12: 11 Equipment | B12: 110000 | C12: 11 | D12: Division11 | F12: TemporaryRamps | G12: 15323 | H12: 1 | I12: 53 | J12: 23 | P12: 15323 | Q12: Temporary Ramps
A13: 12 Furnishings | B13: 120000 | C13: 12 | D13: Division12 | F13: ConstructionAids | G13: 15400 | H13: 1 | I13: 54 | J13: 0 | P13: 15400 | Q13: Construction Aids
A14: 13 Special Construction | B14: 130000 | C14: 13 | D14: Division13 | F14: VehicularAccessandParking | G14: 15500 | H14: 1 | I14: 55 | J14: 0 | P14: 15500 | Q14: Vehicular Access and Parking
A15: 14 Conveying Equipment | B15: 140000 | C15: 14 | D15: Division14 | F15: TemporaryBarriersandEnclosures | G15: 15600 | H15: 1 | I15: 56 | J15: 0 | P15: 15600 | Q15: Temporary Barriers and Enclosures
A16: 21 Fire Suppression | B16: 210000 | C16: 21 | D16: Division21 | F16: TemporaryErosion,Sediment,andPollutionControl | G16: 15713 | H16: 1 | I16: 57 | J16: 13 | P16: 15713 | Q16: Temporary Erosion, Sediment, and Pollution Control
A17: 22 Plumbing | B17: 220000 | C17: 22 | D17: Division22 | F17: ProductStorageandHandlingRequirements | G17: 16600 | H17: 1 | I17: 66 | J17: 0 | P17: 16600 | Q17: Product Storage and Handling Requirements
A18: 23 Heating Ventilating And Air Conditioning | B18: 230000 | C18: 23 | D18: Division23 | F18: CuttingandPatching | G18: 17329 | H18: 1 | I18: 73 | J18: 29 | P18: 17329 | Q18: Cutting and Patching
A19: 26 Electrical | B19: 260000 | C19: 26 | D19: Division26 | F19: CleaningandWasteManagement | G19: 17400 | H19: 1 | I19: 74 | J19: 00 | P19: 17400 | Q19: Cleaning and Waste Management
A20: 27 Communications | B20: 270000 | C20: 27 | D20: Division27 | F20: ConstructionWasteRecycling | G20: 17419 | H20: 1 | I20: 74 | J20: 19 | P20: 17419 | Q20: Construction Waste Recycling
A21: 28 Electronic Safety And Security | B21: 280000 | C21: 28 | D21: Division28 | F21: Commissioning | G21: 19100 | H21: 1 | I21: 91 | J21: 0 | P21: 19100 | Q21: Commissioning
A22: 31 Earthwork | B22: 310000 | C22: 31 | D22: Division31 | P22: SUBGROUP: FACILITY CONSTRUCTION
A23: 32 Exterior Improvements | B23: 320000 | C23: 32 | D23: Division32 | G23: 20000 | H23: 2 | I23: 00 | J23: 00 | P23: Division 02 - Existing Conditions
A24: 33 Utilities | B24: 330000 | C24: 33 | D24: Divsion33 | F24: CommonWorkResultsforExistingConditions | G24: 20500 | H24: 2 | I24: 05 | J24: 00 | P24: 20500 | Q24: Common Work Results for Existing Conditions
A25: 34 Transportation | B25: 340000 | C25: 34 | D25: Division34 | F25: SiteDemolition | G25: 24113 | H25: 2 | I25: 41 | J25: 13 | P25: 24113 | Q25: Site Demolition
A26: 35 Waterway And Marine | B26: 350000 | C26: 35 | D26: Division35 | F26: SelectiveInteriorDemolition | G26: 24119 | H26: 2 | I26: 41 | J26: 19 | P26: 24119 | Q26: Selective Interior Demolition
A27: 41 Material Proc And Handling Eq. | B27: 410000 | C27: 41 | D27: Divsion41 | F27: SiteRemediation | G27: 25000 | H27: 2 | I27: 50 | J27: 00 | P27: 25000 | Q27: Site Remediation
A28: 51 Earthwork FAA | B28: 510000 | C28: 51 | D28: Division51 | F28: RemovalandDisposalofContaminatedSoils | G28: 26100 | H28: 2 | I28: 61 | J28: 00 | P28: 26100 | Q28: Removal and Disposal of Contaminated Soils
A29: 52 Flexible Base Courses FAA | B29: 520000 | C29: 52 | D29: Division52 | F29: UndergroundStorageTankRemoval | G29: 26500 | H29: 2 | I29: 65 | J29: 00 | P29: 26500 | Q29: Underground Storage Tank Removal
A30: 53 Rigid Base Courses FAA | B30: 530000 | C30: 53 | D30: Division53 | F30: GroundwaterTreatment | G30: 27100 | H30: 2 | I30: 71 | J30: 0 | P30: 27100 | Q30: Groundwater Treatment
A31: 54 Flexible Surface Courses FAA | B31: 540000 | C31: 54 | D31: Division54 | F31: AsbestosAbatement | G31: 28213 | H31: 2 | I31: 82 | J31: 13 | P31: 28213 | Q31: Asbestos Abatement
A32: 55 Rigid Pavement FAA | B32: 550000 | C32: 55 | D32: Division55 | F32: AsbestosManagement | G32: 28216 | H32: 2 | I32: 82 | J32: 16 | P32: 28216 | Q32: Asbestos Management
A33: 56 Miscellaneous FAA | B33: 560000 | C33: 56 | D33: Division56 | F33: Lead_BasedPaintManagement | G33: 28313 | H33: 2 | I33: 83 | J33: 13 | P33: 28313 | Q33: Lead-Based Paint Management
A34: 57 Fencing FAA | B34: 570000 | C34: 57 | D34: Division57 | F34: Lead_BasedPaintAbatement | G34: 28319 | H34: 2 | I34: 83 | J34: 19 | P34: 28319 | Q34: Lead-Based Paint Abatement
A35: 58 Drainage FAA | B35: 580000 | C35: 58 | D35: Division58 | F35: PCBRemediation | G35: 28400 | H35: 2 | I35: 84 | J35: 00 | P35: 28400 | Q35: PCB Remediation
A36: 59 Turfing FAA | B36: 590000 | C36: 59 | D36: Division59
A37: 60 Lighting Installation FAA | B37: 600000 | C37: 60 | D37: Division60 | G37: 30000 | H37: 3 | I37: 00 | J37: 00 | P37: Division 03 - Concrete
F38: CommonWorkResultsforConcrete | G38: 30500 | H38: 3 | I38: 05 | J38: 00 | P38: 30500 | Q38: Common Work Results for Concrete
F39: ConcreteFormwork | G39: 31100 | H39: 3 | I39: 11 | J39: 00 | P39: 31100 | Q39: Concrete Formwork
F40: ConcreteAccessories | G40: 31500 | H40: 3 | I40: 15 | J40: 00 | P40: 31500 | Q40: Concrete Accessories
...

Sheet Soft Cost Codes
A1: Shrt | B1: Division | C1: Description | D1: Lookup | E1: SubType | F1: Cost Code | G1: Seg1 | H1: Seg2 | I1: Seg3 | K1: SubType | L1: Cost Code | M1: Seg1 | N1: Seg2 | O1: Seg3
A2: SIT | B2: Division 1 | C2: Channel_Deepening_Site_Channel_Deepening | D2: Channel_Deepening_Site_Channel_Deepening_Acquisition | E2: Acquisition | F2: 160000 | G2: 16 | H2: 0 | I2: 0 | K2: ProjectAdminMgmt | L2: 100000 | M2: 10 | N2: 0 | O2: 0
A3: SIT | B3: Division 1 | C3: Channel_Deepening_Site_Channel_Deepening | E3: General | F3: 161000 | G3: 16 | H3: 10 | I3: 0 | K3: General | L3: 101000 | M3: 10 | N3: 10 | O3: 0
A4: SIT | B4: Division 1 | C4: Channel_Deepening_Site_Channel_Deepening | E4: Demolition | F4: 161200 | G4: 16 | H4: 12 | I4: 0 | K4: ProjectAdminandMgmt | L4: 100000 | M4: 10 | N4: 0 | O4: 0
A5: SIT | B5: Division 1 | C5: Channel_Deepening_Site_Channel_Deepening | E5: RelocationAssistance | F5: 161300 | G5: 16 | H5: 13 | I5: 0 | K5: LandAcquisition | L5: 101600 | M5: 10 | N5: 16 | O5: 0
A6: SIT | B6: Division 1 | C6: Channel_Deepening_Site_Channel_Deepening | E6: Appraisals | F6: 161400 | G6: 16 | H6: 14 | I6: 0 | K6: FinancialSupport | L6: 101700 | M6: 10 | N6: 17 | O6: 0
A7: SIT | B7: Division 1 | C7: Channel_Deepening_Site_Channel_Deepening | E7: EnvironmentalAssessments | F7: 161500 | G7: 16 | H7: 15 | I7: 0 | K7: LegislativeFunding | L7: 101800 | M7: 10 | N7: 18 | O7: 0
A8: SIT | B8: Division 1 | C8: Channel_Deepening_Site_Channel_Deepening | E8: Condemnation | F8: 161600 | G8: 16 | H8: 16 | I8: 0 | K8: Agreements | L8: 101900 | M8: 10 | N8: 19 | O8: 0
A9: SIT | B9: Division 1 | C9: Channel_Deepening_Site_Channel_Deepening | E9: Inspection | F9: 161700 | G9: 16 | H9: 17 | I9: 0 | K9: ProjectMgmt | L9: 101200 | M9: 10 | N9: 12 | O9: 0
A10: SIT | B10: Division 1 | C10: Channel_Deepening_Site_Channel_Deepening | E10: TitleWork | F10: 161800 | G10: 16 | H10: 18 | I10: 0 | K10: UplandSourceControlProgramCoordination | L10: 101010 | M10: 10 | N10: 10 | O10: 10
A11: SIT | B11: Division 1 | C11: Channel_Deepening_Site_Channel_Deepening | E11: Survey | F11: 162200 | G11: 16 | H11: 22 | I11: 0 | K11: ProgramManagement | L11: 101020 | M11: 10 | N11: 10 | O11: 20
A12: SIT | B12: Division 1 | C12: Channel_Deepening_Site_Channel_Deepening | D12: Channel_Deepening_Site_Channel_Deepening_Permitting | E12: Permitting | F12: 200000 | G12: 20 | H12: 0 | I12: 0 | K12: Meetings | L12: 101100 | M12: 10 | N12: 11 | O12: 0
A13: SIT | B13: Division 1 | C13: Channel_Deepening_Site_Channel_Deepening | E13: General | F13: 201000 | G13: 20 | H13: 10 | I13: 0 | K13: Development | L13: 101300 | M13: 10 | N13: 13 | O13: 0
A14: SIT | B14: Division 1 | C14: Channel_Deepening_Site_Channel_Deepening | D14: Channel_Deepening_Site_Channel_Deepening_Contingency | E14: Contingency | F14: 790000 | G14: 79 | H14: 0 | I14: 0 | K14: Design | L14: 101400 | M14: 10 | N14: 14 | O14: 0
A15: UPL | B15: Division 1 | C15: Upland_Control_Sites_Lower_Willamette | D15: Upland_Control_Sites_Lower_Willamette_ProjectAdminMgmt | E15: ProjectAdminMgmt | F15: 100000 | G15: 10 | H15: 0 | I15: 0 | K15: Construction | L15: 101500 | M15: 10 | N15: 15 | O15: 0
A16: UPL | B16: Division 1 | C16: Upland_Control_Sites_Lower_Willamette | E16: General | F16: 101000 | G16: 10 | H16: 10 | I16: 0 | K16: Develop | L16: 101300 | M16: 10 | N16: 13 | O16: 0
A17: UPL | B17: Division 1 | C17: Upland_Control_Sites_Lower_Willamette | D17: Upland_Control_Sites_Lower_Willamette_Design | E17: Design | F17: 140000 | G17: 14 | H17: 0 | I17: 0 | K17: BusinessContinuity | L17: 110000 | M17: 11 | N17: 0 | O17: 0
A18: UPL | B18: Division 1 | C18: Upland_Control_Sites_Lower_Willamette | E18: OutsideDesignServices | F18: 141010 | G18: 14 | H18: 10 | I18: 10 | K18: General | L18: 111000 | M18: 11 | N18: 10 | O18: 0
A19: UPL | B19: Division 1 | C19: Upland_Control_Sites_Lower_Willamette | E19: TreatabilityStudy_PilotTesting | F19: 141300 | G19: 14 | H19: 13 | I19: 0 | K19: AnalysisandRequirementsDefinition | L19: 120000 | M19: 12 | N19: 0 | O19: 0
A20: UPL | B20: Division 1 | C20: Upland_Control_Sites_Lower_Willamette | E20: RemedialDesign | F20: 141400 | G20: 14 | H20: 14 | I20: 0 | K20: General | L20: 121000 | M20: 12 | N20: 10 | O20: 0
A21: UPL | B21: Division 1 | C21: Upland_Control_Sites_Lower_Willamette | E21: Enviornmental | F21: 141600 | G21: 14 | H21: 16 | I21: 0 | K21: DevelopandIssueRFP | L21: 121100 | M21: 12 | N21: 11 | O21: 0
A22: UPL | B22: Division 1 | C22: Upland_Control_Sites_Lower_Willamette | E22: PEDesign | F22: 141700 | G22: 14 | H22: 17 | I22: 0 | K22: SelectVendor | L22: 121200 | M22: 12 | N22: 12 | O22: 0
A23: UPL | B23: Division 1 | C23: Upland_Control_Sites_Lower_Willamette | E23: ITDesignSupport | F23: 142600 | G23: 14 | H23: 26 | I23: 0 | K23: Security | L23: 130000 | M23: 13 | N23: 0 | O23: 0
A24: UPL | B24: Division 1 | C24: Upland_Control_Sites_Lower_Willamette | E24: MaintenanceDesignSupport | F24: 142700 | G24: 14 | H24: 27 | I24: 0 | K24: General | L24: 131000 | M24: 13 | N24: 10 | O24: 0
A25: UPL | B25: Division 1 | C25: Upland_Control_Sites_Lower_Willamette | D25: Upland_Control_Sites_Lower_Willamette_Planning | E25: Planning | F25: 150000 | G25: 15 | H25: 0 | I25: 0 | K25: Design | L25: 140000 | M25: 14 | N25: 0 | O25: 0
A26: UPL | B26: Division 1 | C26: Upland_Control_Sites_Lower_Willamette | E26: AssessmentPlanning | F26: 151100 | G26: 15 | H26: 11 | I26: 0 | K26: OutsideDesignServices | L26: 141010 | M26: 14 | N26: 10 | O26: 10
A27: UPL | B27: Division 1 | C27: Upland_Control_Sites_Lower_Willamette | E27: PreliminaryAssessment | F27: 151110 | G27: 15 | H27: 11 | I27: 10 | K27: TreatabilityStudy_PilotTesting | L27: 141300 | M27: 14 | N27: 13 | O27: 0
A28: UPL | B28: Division 1 | C28: Upland_Control_Sites_Lower_Willamette | E28: SiteInvestigation | F28: 151200 | G28: 15 | H28: 12 | I28: 0 | K28: RemedialDesign | L28: 141400 | M28: 14 | N28: 14 | O28: 0
A29: UPL | B29: Division 1 | C29: Upland_Control_Sites_Lower_Willamette | E29: RemedialInvestigation | F29: 151300 | G29: 15 | H29: 13 | I29: 0 | K29: Enviornmental | L29: 141600 | M29: 14 | N29: 16 | O29: 0
A30: UPL | B30: Division 1 | C30: Upland_Control_Sites_Lower_Willamette | E30: CargillOU1 | F30: 151310 | G30: 15 | H30: 13 | I30: 10 | K30: PEDesign | L30: 141700 | M30: 14 | N30: 17 | O30: 0
A31: UPL | B31: Division 1 | C31: Upland_Control_Sites_Lower_Willamette | E31: OU2 | F31: 151320 | G31: 15 | H31: 13 | I31: 20 | K31: ITDesignSupport | L31: 142600 | M31: 14 | N31: 26 | O31: 0
A32: UPL | B32: Division 1 | C32: Upland_Control_Sites_Lower_Willamette | E32: FeasibilityStudy | F32: 151600 | G32: 15 | H32: 16 | I32: 0 | K32: MaintenanceDesignSupport | L32: 142700 | M32: 14 | N32: 27 | O32: 0
A33: UPL | B33: Division 1 | C33: Upland_Control_Sites_Lower_Willamette | E33: CulturalResources | F33: 151700 | G33: 15 | H33: 17 | I33: 0 | K33: Environmental | L33: 141600 | M33: 14 | N33: 16 | O33: 0
A34: UPL | B34: Division 1 | C34: Upland_Control_Sites_Lower_Willamette | D34: Upland_Control_Sites_Lower_Willamette_Development | E34: Development | F34: 170000 | G34: 17 | H34: 0 | I34: 0 | K34: Survey | L34: 141800 | M34: 14 | N34: 18 | O34: 0
A35: UPL | B35: Division 1 | C35: Upland_Control_Sites_Lower_Willamette | E35: OutsideDesignServices | F35: 171510 | G35: 17 | H35: 15 | I35: 10 | K35: CAD | L35: 142200 | M35: 14 | N35: 22 | O35: 0
A36: UPL | B36: Division 1 | C36: Upland_Control_Sites_Lower_Willamette | D36: Upland_Control_Sites_Lower_Willamette_Implementation | E36: Implementation | F36: 180000 | G36: 18 | H36: 0 | I36: 0 | K36: BidPackage | L36: 142300 | M36: 14 | N36: 23 | O36: 0
A37: UPL | B37: Division 1 | C37: Upland_Control_Sites_Lower_Willamette | E37: RemedialAction | F37: 181000 | G37: 18 | H37: 10 | I37: 0 | K37: General | L37: 141000 | M37: 14 | N37: 10 | O37: 0
A38: UPL | B38: Division 1 | C38: Upland_Control_Sites_Lower_Willamette | E38: OandM_Systems | F38: 181100 | G38: 18 | H38: 11 | I38: 0 | K38: ESAReconsulation | L38: 142400 | M38: 14 | N38: 24 | O38: 0
A39: UPL | B39: Division 1 | C39: Upland_Control_Sites_Lower_Willamette | E39: OandM_Monitoring | F39: 181200 | G39: 18 | H39: 12 | I39: 0 | K39: UtilityRelocations | L39: 142500 | M39: 14 | N39: 25 | O39: 0
A40: UPL | B40: Division 1 | C40: Upland_Control_Sites_Lower_Willamette | D40: Upland_Control_Sites_Lower_Willamette_Construction | E40: Construction | F40: 190000 | G40: 19 | H40: 0 | I40: 0 | K40: Restoration | L40: 141500 | M40: 14 | N40: 15 | O40: 0
...

Sheet Cost Codes
A1: SUBGROUP: GENERAL REQUIREMENTS
A2: Division 01 - General Requirements
A3: 13100 | B3: Contractor's Management and Coordination
A4: 13300 | B4: Submittal Procedures
A5: 13500 | B5: Security Control
A6: 13501 | B6: Escort
A7: 14100 | B7: Permits
A8: 15000 | B8: Mobilization and Demobilization
A9: 15001 | B9: Traffic Control
A10: 15002 | B10: Sweeping
A11: 15123 | B11: Temporary Heating, Cooling and Ventilating
A12: 15323 | B12: Temporary Ramps
A13: 15400 | B13: Construction Aids
A14: 15500 | B14: Vehicular Access and Parking
... A21: 19100 | B21: Commissioning
A22: SUBGROUP: FACILITY CONSTRUCTION
A23: Division 02 - Existing Conditions
A24: 20500 | B24: Common Work Results for Existing Conditions
A25: 24113 | B25: Site Demolition
A26: 24119 | B26: Selective Interior Demolition
A27: 25000 | B27: Site Remediation
A28: 26100 | B28: Removal and Disposal of Contaminated Soils
A29: 26500 | B29: Underground Storage Tank Removal
A30: 27100 | B30: Groundwater Treatment
A31: 28213 | B31: Asbestos Abatement
A32: 28216 | B32: Asbestos Management
A33: 28313 | B33: Lead-Based Paint Management
A34: 28319 | B34: Lead-Based Paint Abatement
A35: 28400 | B35: PCB Remediation
A36: Division 03 - Concrete
A37: 30500 | B37: Common Work Results for Concrete
A38: 31100 | B38: Concrete Formwork
A39: 31500 | B39: Concrete Accessories
A40: 32000 | B40: Concrete Reinforcing
A41: 33000 | B41: Cast-In-Place Concrete
A42: 36000 | B42: Concrete Grouting
A43: Division 04 - Masonry
A44: 40500 | B44: Common Work Results for Masonry
A45: 40513 | B45: Masonry Mortar and Grout
A46: 40523 | B46: Masonry Accessories
...

Sheet UoM
B1: Hard Cost
B2: UoM | C2: % | D2: 1 | E2: Standard View
B3: UoM | C3: Acre | D3: 2 | E3: Engineering Planning View
B4: UoM | C4: CY | D4: 4
B5: UoM | C5: Day | D5: 5
B6: UoM | C6: Ea | D6: 6
B7: UoM | C7: Gal | D7: 7
B8: UoM | C8: Hr | D8: 8
B9: UoM | C9: Lb | D9: 9
B10: UoM | C10: LF | D10: 10
B11: UoM | C11: LS
B12: UoM | C12: SF
B13: UoM | C13: SY
B14: UoM | C14: Ton
B15: UoM | C15: Week
C16: Job

Sheet SoftCostUom
F1: Soft Cost
F2: UoM | G2: % | H2: 1
F3: UoM | G3: Week | H3: 2
F4: UoM | G4: Day | H4: 4
F5: UoM | G5: Hr | H5: 5
F6: UoM | G6: Ea | H6: 6
F7: UoM | G7: LS | H7: 7
G8: Job

Sheet Scope and Risk
E1: Risk Breakdown Structure | F1: Code
E2: People | F2: P
B3: Scope Accuracy: | C3: Level 1: Project scope well understood and well defined | D3: People | E3: PEOPLE: Unavailable resources - Engineering (P1) | F3: P1
B4: Scope Accuracy: | C4: Level 2: Project scope conceptual | D4: People | E4: PEOPLE: Unavailable resources - IT (P2) | F4: P2
B5: Scope Accuracy: | C5: Level 3: Project scope is a "vision" with limited detail | D5: People | E5: PEOPLE: Unavailable resources - Project (P3) | F5: P3
D6: People | E6: PEOPLE: Unavailable resources - Business (P4) | F6: P4
D7: People | E7: PEOPLE: Unavailable resources - Sponsor (P5) | F7: P5
B8: Engineering Effort: | C8: Level A: Preliminary engineering performed | D8: People | E8: PEOPLE: Difficulty staffing resources (P6) | F8: P6
B9: Engineering Effort: | C9: Level B: Conceptual engineering performed | D9: People | E9: PEOPLE: Loss of key people - Engineering (P7) | F9: P7
B10: Engineering Effort: | C10: Level C: No engineering performed | D10: People | E10: PEOPLE: Loss of key people - IT (P8) | F10: P8
D11: People | E11: PEOPLE: Loss of key people - Business (P9) | F11: P9
D12: People | E12: PEOPLE: Conflicts interfere with progress (P10) | F12: P10
D13: People | E13: PEOPLE: Resources lack required skills, experience, fit - Engineering (P11) | F13: P11
C14: Project Charter | D14: People | E14: PEOPLE: Resources lack required skills, experience, fit - IT (P12) | F14: P12
C15: Business Case - Gate 1 | D15: People | E15: PEOPLE: Resources lack required skills, experience, fit - Business (P13) | F15: P13
C16: Preliminary Design - Gate 2 | D16: People | E16: PEOPLE: Insufficient onboarding of new project staff (P14) | F16: P14
C17: 100% Design/ Pre-Bid - Gate 3 | D17: People | E17: PEOPLE: Human error (P15) | F17: P15
C18: Bid Acceptance - Gate 4 | D18: People | E18: PEOPLE: Project teams lacked sufficient understanding of new technology (P16) | F18: P16
C19: Project Closeout - Gate 5 | D19: People | E19: PEOPLE: Inability to scale specialty skills (P17) | F19: P17
D20: Requirements | E20: Requirements | F20: R
D21: Requirements | E21: REQUIREMENTS: Project outcomes or scope unclear (R1) | F21: R1
D22: Requirements | E22: REQUIREMENTS: Stakeholders not well understood (R2) | F22: R2
C23: Stage Gate 1 - Project Charter: +/-50% | D23: Requirements | E23: REQUIREMENTS: Error or omissions in requirements (R3) | F23: R3
C24: Stage Gate 2 - Business Case: +/-30% | D24: Requirements | E24: REQUIREMENTS: Significant learning, new ground (R4) | F24: R4
C25: Stage Gate 3 - Preliminary Planning: +/-25% | D25: Requirements | E25: REQUIREMENTS: Shifting business timelines, priorities (R5) | F25: R5
C26: Stage Gate 4a - 30% Design: -15% to +20% | D26: Requirements | E26: REQUIREMENTS: Inability to accurately translate business requirements into infrastructure scope (R6) | F26: R6
C27: Stage Gate 4a - 60% Design: -10% to +15% | D27: Requirements | E27: REQUIREMENTS: Unforeseen complexity or understanding of infrastructure (R7) | F27: R7
C28: Stage Gate 4a - 90% Design: +/-10% | D28: Requirements | E28: REQUIREMENTS: Mismatch of expectations between customers, sponsors, vendors (R8) | F28: R8
C29: Stage Gate 4b - CD Design: +/-5% | E29: Process | F29: PRC
D30: Process | E30: PROCESS: Poor work breakdown or estimating (PRC1) | F30: PRC1
C31: Percentage Based | D31: Process | E31: PROCESS: Operational processes not well understood (PRC2) | F31: PRC2
C32: Hourly Estimate | D32: Process | E32: PROCESS: Insufficient understanding of environmental complexity, dependencies (PRC3) | F32: PRC3
D33: Process | E33: PROCESS: Delays in reviews, approvals, decision-making problems (PRC4) | F33: PRC4
D34: Process | E34: PROCESS: Management or escalation problems (PRC5) | F34: PRC5
D35: Process | E35: PROCESS: Sliced work or unclear hand-offs (PRC6) | F35: PRC6
D36: Process | E36: PROCESS: Delivery methodology not well applied (PRC7) | F36: PRC7
D37: Process | E37: PROCESS: Unclear roles and responsibilities (PRC8) | F37: PRC8
D38: Process | E38: PROCESS: Gatekeepers or assessors lack skill, knowledge to make gate assessments/decisions (PRC9) | F38: PRC9
D39: Process | E39: PROCESS: Skill or accountability gap on complex end-to-end architecture/engineering solutions versus product solution (PRC10) | F39: PRC10
D40: Process | E40: PROCESS: Insufficient engagement to prepare estimates (PRC11) | F40: PRC11
...
