Workbook
Name Contractor1: 'Bid Tabulation'!$E$1
Name Contractor2: 'Bid Tabulation'!$G$1
Name Contractor3: 'Bid Tabulation'!$I$1
Name Contractor3A: 'Bid Tabulation'!#REF!
Name Contractor4: 'Bid Tabulation'!$K$1
Name Contractor5: 'Bid Tabulation'!$M$1
Name Contractor6: 'Bid Tabulation'!$O$1
Name Contractor7: 'Bid Tabulation'!$Q$1
Name Contractor8: 'Bid Tabulation'!#REF!
Name EAN: 'Bid Tabulation'!$A$4
Name EngineerEstimate: 'Bid Tabulation'!$S$1
Name ProjectLocation: 'Bid Item List'!$A$15
Name ProjectTitle: 'Bid Item List'!$A$16
Name ProjectTitle2: 'Bid Item List'!$A$17
Name QTY: 'Bid Tabulation'!$C:$C
Name SolicitationNo: 'Bid Tabulation'!$A$5
Name Total1: 'Bid Tabulation'!$F$55
Name Total2: 'Bid Tabulation'!$H$55
Name Total3: 'Bid Tabulation'!$J$55
Name Total3A: 'Bid Tabulation'!#REF!
Name Total4: 'Bid Tabulation'!$L$55
Name Total5: 'Bid Tabulation'!$N$55
Name Total6: 'Bid Tabulation'!$P$55
Name Total7: 'Bid Tabulation'!$R$55
Name Total8: 'Bid Tabulation'!#REF!
Name TotalEE: 'Bid Tabulation'!$T$55

Sheet Bid Item List
A1: Acre
A2: CY
A3: Each
A4: FT
A5: Gal
A6: Hour
A7: LB
A8: LF
A9: LS
A10: Mile
A11: SF
A12: SY
... A16: NORTH RAMP RON PARKING RECONSTRUCTION
A19: Item No. | B19: Item Description | C19: Estimated Quantity | D19: Units | E19: Unit Price | F19: Total Price
A20: 0001 | B20: Mobilization, Cleanup, and Demobilization (Section 012200) | C20: 1 | D20: LS
A21: 0002 | B21: Sweeper (Section 012200) | C21: 1 | D21: LS
A22: 0003 | B22: Security Control Monitoring (Section 012200) | C22: 1 | D22: LS
A23: 0004 | B23: Work Zone and Traffic Control (Section 012200) | C23: 1 | D23: LS
A24: 0005 | B24: Escort (Section 012200) | C24: 1 | D24: LS
A25: 0006 | B25: Construction Survey (Section 012200) | C25: 1 | D25: LS
A26: 0007 | B26: Abandon Existing Monitoring Well (Section 012200) | C26: 1 | D26: Each
A27: 0008 | B27: Inlet Protection (Section 015713) | C27: 36 | D27: Each
A28: 0009 | B28: Trench Drain Protection (Section 015713) | C28: 975 | D28: LF
A29: 0010 | B29: Sediment Fence (Section 015713) | C29: 4655 | D29: LF
A30: 0011 | B30: Building Demolition (Section 024113) | C30: 1 | D30: LS
A31: 0012 | B31: Building Slab and Foundation Removal (Section 024113) | C31: 1 | D31: LS
... A41: 0022 | B41: Removal of Pipe and other Buried Structures (Item P-101) | C41: 1 | D41: LS
A42: 0023 | B42: Unclassified Excavation (Item P-152) | C42: =560+35962 -> 36522 | D42: CY
A43: 0024 | B43: Unsuitable Excavation (Item P-152) | C43: 1157 | D43: CY
A44: 0025 | B44: Separation Geotextile (Item P-152) | C44: 34818 | D44: SY
A45: 0026 | B45: Controlled Low Strength Material (Item P-153) | C45: 200 | D45: CY
A46: 0027 | B46: Crushed Aggregate Base Course (Item P-209) | C46: 6395 | D46: CY
A47: 0028 | B47: Asphalt Surface Course (Item P-401) | C47: 877 | D47: Ton
A48: 0029 | B48: Asphalt Mixture Base Course (Item P-403) | C48: 9975 | D48: Ton
A49: 0030 | B49: 15-Inch Thick Concrete Pavement (Item P-501) | C49: 440 | D49: SY
A50: 0031 | B50: 19-Inch Thick Concrete Pavement (Item P-501) | C50: 30790 | D50: SY
A51: 0032 | B51: Emulsified Asphalt Tack Coat (Item P-603) | C51: 2794 | D51: Gal
A52: 0033 | B52: Compression Joint Seals for Concrete Pavements (Item P-604) | C52: 28932 | D52: LF
A53: 0034 | B53: Joint Sealing Filler (Item P-605) | C53: 12 | D53: Gal
A54: 0035 | B54: Asphalt Surface Treatment (Item P-608) | C54: 106 | D54: SY
...

Sheet Bid Tabulation
A1: =ProjectLocation -> PORTLAND INTERNATIONAL AIRPORT | E1: Goodfellows Bros. LLC | G1: K&E Excavating, Inc. | I1: Kerr Contractors Oregon LLC | K1: Kodiak Pacific Construction | M1: Nutter Corporation | O1: Tapani, Inc. | Q1: Weitman Excavation | S1: Engineer's Estimate
A2: =ProjectTitle -> NORTH RAMP RON PARKING RECONSTRUCTION
A3: =ProjectTitle2 -> 0
A4: EAN 2018D029
A5: Solicitation No. 2020-8113
A6: =TODAY() -> 43844
A7: Item No. | B7: Item Description | C7: Estimated Quantity | D7: Units | E7: Unit Price | F7: Total Price | G7: Unit Price | H7: Total Price | I7: Unit Price | J7: Total Price | K7: Unit Price | L7: Total Price | M7: Unit Price | N7: Total Price | O7: Unit Price | P7: Total Price | Q7: Unit Price | R7: Total Price | S7: Unit Price | T7: Total Price
A8: ='Bid Item List'!A20 -> 0001 | B8: ='Bid Item List'!B20 -> Mobilization, Cleanup, and Demobilization (Section 012200) | C8: ='Bid Item List'!C20 -> 1 | D8: ='Bid Item List'!D20 -> LS | E8: 1200000 | F8: =QTY*E8 -> 1200000 | G8: 1100000 | H8: =QTY*G8 -> 1100000 | I8: 948389 | J8: =QTY*I8 -> 948389 | K8: 699231.4 | L8: =QTY*K8 -> 699231.4 | M8: 842000 | N8: =QTY*M8 -> 842000 | O8: 914000 | P8: =QTY*O8 -> 914000 | Q8: 1007000 | R8: =QTY*Q8 -> 1007000 | S8: 769120 | T8: =QTY*S8 -> 769120
A9: ='Bid Item List'!A21 -> 0002 | B9: ='Bid Item List'!B21 -> Sweeper (Section 012200) | C9: ='Bid Item List'!C21 -> 1 | D9: ='Bid Item List'!D21 -> LS | E9: 112000 | F9: =QTY*E9 -> 112000 | G9: 250000 | H9: =QTY*G9 -> 250000 | I9: 247200 | J9: =QTY*I9 -> 247200 | K9: 270000 | L9: =QTY*K9 -> 270000 | M9: 250000 | N9: =QTY*M9 -> 250000 | O9: 215000 | P9: =QTY*O9 -> 215000 | Q9: 229000 | R9: =QTY*Q9 -> 229000 | S9: 100000 | T9: =QTY*S9 -> 100000
A10: ='Bid Item List'!A22 -> 0003 | B10: ='Bid Item List'!B22 -> Security Control Monitoring (Section 012200) | C10: ='Bid Item List'!C22 -> 1 | D10: ='Bid Item List'!D22 -> LS | E10: 250000 | F10: =QTY*E10 -> 250000 | G10: 10000 | H10: =QTY*G10 -> 10000 | I10: 83750 | J10: =QTY*I10 -> 83750 | K10: 4400 | L10: =QTY*K10 -> 4400 | M10: 105000 | N10: =QTY*M10 -> 105000 | O10: 85000 | P10: =QTY*O10 -> 85000 | Q10: 21000 | R10: =QTY*Q10 -> 21000 | S10: 50000 | T10: =QTY*S10 -> 50000
A11: ='Bid Item List'!A23 -> 0004 | B11: ='Bid Item List'!B23 -> Work Zone and Traffic Control (Section 012200) | C11: ='Bid Item List'!C23 -> 1 | D11: ='Bid Item List'!D23 -> LS | E11: 125000 | F11: =QTY*E11 -> 125000 | G11: 80000 | H11: =QTY*G11 -> 80000 | I11: 155250 | J11: =QTY*I11 -> 155250 | K11: 89500 | L11: =QTY*K11 -> 89500 | M11: 50000 | N11: =QTY*M11 -> 50000 | O11: 50000 | P11: =QTY*O11 -> 50000 | Q11: 66000 | R11: =QTY*Q11 -> 66000 | S11: 100000 | T11: =QTY*S11 -> 100000
A12: ='Bid Item List'!A24 -> 0005 | B12: ='Bid Item List'!B24 -> Escort (Section 012200) | C12: ='Bid Item List'!C24 -> 1 | D12: ='Bid Item List'!D24 -> LS | E12: 50000 | F12: =QTY*E12 -> 50000 | G12: 230000 | H12: =QTY*G12 -> 230000 | I12: 323400 | J12: =QTY*I12 -> 323400 | K12: 248000 | L12: =QTY*K12 -> 248000 | M12: 100000 | N12: =QTY*M12 -> 100000 | O12: 325000 | P12: =QTY*O12 -> 325000 | Q12: 270000 | R12: =QTY*Q12 -> 270000 | S12: 225000 | T12: =QTY*S12 -> 225000
A13: ='Bid Item List'!A25 -> 0006 | B13: ='Bid Item List'!B25 -> Construction Survey (Section 012200) | C13: ='Bid Item List'!C25 -> 1 | D13: ='Bid Item List'!D25 -> LS | E13: 90000 | F13: =QTY*E13 -> 90000 | G13: 150000 | H13: =QTY*G13 -> 150000 | I13: 85000 | J13: =QTY*I13 -> 85000 | K13: 53500 | L13: =QTY*K13 -> 53500 | M13: 82000 | N13: =QTY*M13 -> 82000 | O13: 125000 | P13: =QTY*O13 -> 125000 | Q13: 130000 | R13: =QTY*Q13 -> 130000 | S13: 175000 | T13: =QTY*S13 -> 175000
A14: ='Bid Item List'!A26 -> 0007 | B14: ='Bid Item List'!B26 -> Abandon Existing Monitoring Well (Section 012200) | C14: ='Bid Item List'!C26 -> 1 | D14: ='Bid Item List'!D26 -> Each | E14: 2500 | F14: =QTY*E14 -> 2500 | G14: 5000 | H14: =QTY*G14 -> 5000 | I14: 3000 | J14: =QTY*I14 -> 3000 | K14: 3050 | L14: =QTY*K14 -> 3050 | M14: 6000 | N14: =QTY*M14 -> 6000 | O14: 5500 | P14: =QTY*O14 -> 5500 | Q14: 1600 | R14: =QTY*Q14 -> 1600 | S14: 3500 | T14: =QTY*S14 -> 3500
A15: ='Bid Item List'!A27 -> 0008 | B15: ='Bid Item List'!B27 -> Inlet Protection (Section 015713) | C15: ='Bid Item List'!C27 -> 36 | D15: ='Bid Item List'!D27 -> Each | E15: 135 | F15: =QTY*E15 -> 4860 | G15: 85 | H15: =QTY*G15 -> 3060 | I15: 115 | J15: =QTY*I15 -> 4140 | K15: 108 | L15: =QTY*K15 -> 3888 | M15: 160 | N15: =QTY*M15 -> 5760 | O15: 55 | P15: =QTY*O15 -> 1980 | Q15: 125 | R15: =QTY*Q15 -> 4500 | S15: 100 | T15: =QTY*S15 -> 3600
A16: ='Bid Item List'!A28 -> 0009 | B16: ='Bid Item List'!B28 -> Trench Drain Protection (Section 015713) | C16: ='Bid Item List'!C28 -> 975 | D16: ='Bid Item List'!D28 -> LF | E16: 3 | F16: =QTY*E16 -> 2925 | G16: 5 | H16: =QTY*G16 -> 4875 | I16: 2.5 | J16: =QTY*I16 -> 2437.5 | K16: 7 | L16: =QTY*K16 -> 6825 | M16: 3 | N16: =QTY*M16 -> 2925 | O16: 5 | P16: =QTY*O16 -> 4875 | Q16: 2 | R16: =QTY*Q16 -> 1950 | S16: 2 | T16: =QTY*S16 -> 1950
A17: ='Bid Item List'!A29 -> 0010 | B17: ='Bid Item List'!B29 -> Sediment Fence (Section 015713) | C17: ='Bid Item List'!C29 -> 4655 | D17: ='Bid Item List'!D29 -> LF | E17: 4 | F17: =QTY*E17 -> 18620 | G17: 2.6 | H17: =QTY*G17 -> 12103 | I17: 2.4 | J17: =QTY*I17 -> 11172 | K17: 2.5 | L17: =QTY*K17 -> 11637.5 | M17: 3 | N17: =QTY*M17 -> 13965 | O17: 3.25 | P17: =QTY*O17 -> 15128.75 | Q17: 4 | R17: =QTY*Q17 -> 18620 | S17: 2.5 | T17: =QTY*S17 -> 11637.5
A18: ='Bid Item List'!A30 -> 0011 | B18: ='Bid Item List'!B30 -> Building Demolition (Section 024113) | C18: ='Bid Item List'!C30 -> 1 | D18: ='Bid Item List'!D30 -> LS | E18: 100000 | F18: =QTY*E18 -> 100000 | G18: 80000 | H18: =QTY*G18 -> 80000 | I18: 75150 | J18: =QTY*I18 -> 75150 | K18: 39800 | L18: =QTY*K18 -> 39800 | M18: 80000 | N18: =QTY*M18 -> 80000 | O18: 100000 | P18: =QTY*O18 -> 100000 | Q18: 90000 | R18: =QTY*Q18 -> 90000 | S18: 285000 | T18: =QTY*S18 -> 285000
A19: ='Bid Item List'!A31 -> 0012 | B19: ='Bid Item List'!B31 -> Building Slab and Foundation Removal (Section 024113) | C19: ='Bid Item List'!C31 -> 1 | D19: ='Bid Item List'!D31 -> LS | E19: 100000 | F19: =QTY*E19 -> 100000 | G19: 80000 | H19: =QTY*G19 -> 80000 | I19: 372540 | J19: =QTY*I19 -> 372540 | K19: 113000 | L19: =QTY*K19 -> 113000 | M19: 75000 | N19: =QTY*M19 -> 75000 | O19: 65000 | P19: =QTY*O19 -> 65000 | Q19: 83000 | R19: =QTY*Q19 -> 83000 | S19: 100000 | T19: =QTY*S19 -> 100000
... A87: ='Bid Item List'!A99 -> 0080 | B87: ='Bid Item List'!B99 -> Ditch Protection/Check Dams (Section 015713) | C87: ='Bid Item List'!C99 -> 5 | D87: ='Bid Item List'!D99 -> Each | E87: 500 | F87: =QTY*E87 -> 2500 | G87: 100 | H87: =QTY*G87 -> 500 | I87: 145 | J87: =QTY*I87 -> 725 | K87: 135 | L87: =QTY*K87 -> 675 | M87: 200 | N87: =QTY*M87 -> 1000 | O87: 120 | P87: =QTY*O87 -> 600 | Q87: 200 | R87: =QTY*Q87 -> 1000 | S87: 175 | T87: =QTY*S87 -> 875
B88: ='Bid Item List'!B100 -> Total Amount Bid (Basis of Award) | D88: ='Bid Item List'!D100 -> 0 | F88: =SUM(F8:F87) -> 14365415 | H88: =SUM(H8:H87) -> 11259886 | J88: =SUM(J8:J87) -> 11998920 | L88: =SUM(L8:L87) -> 10558558 | N88: =SUM(N8:N87) -> 11071755 | P88: =SUM(P8:P87) -> 10834563 | R88: =SUM(R8:R87) -> 10142018 | T88: =SUM(T8:T87) -> 11033119

Sheet Summary
A1: =ProjectLocation -> PORTLAND INTERNATIONAL AIRPORT
A2: =ProjectTitle -> NORTH RAMP RON PARKING RECONSTRUCTION
A3: =ProjectTitle2 -> 0
A4: =EAN -> EAN 2018D029
A5: =SolicitationNo -> Solicitation No. 2020-8113
A6: =TODAY() -> 43844
A7: Bidder | B7: Total Price
A8: =Contractor7 -> Weitman Excavation | B8: ='Bid Tabulation'!R88 -> 10142018
A9: =Contractor4 -> Kodiak Pacific Construction | B9: ='Bid Tabulation'!L88 -> 10558558
A10: =Contractor6 -> Tapani, Inc. | B10: $10,834,562.95*
A11: =Contractor5 -> Nutter Corporation | B11: ='Bid Tabulation'!N88 -> 11071755
A12: =Contractor2 -> K&E Excavating, Inc. | B12: ='Bid Tabulation'!H88 -> 11259886
A13: =Contractor3 -> Kerr Contractors Oregon LLC | B13: ='Bid Tabulation'!J88 -> 11998920
A14: =Contractor1 -> Goodfellows Bros. LLC | B14: $14,365,415.00*
A15: =EngineerEstimate -> Engineer's Estimate | B15: ='Bid Tabulation'!T88 -> 11033119
A16: *Corrected Bid Total
