Workbook
Name Contractor1: 'Bid Tab A (FAA)'!$E$1
Name Contractor1: 'Bid Tab B (Port)'!$E$1
Name Contractor2: 'Bid Tab A (FAA)'!$G$1
Name Contractor2: 'Bid Tab B (Port)'!$G$1
Name Contractor3: 'Bid Tab A (FAA)'!$I$1
Name Contractor3: 'Bid Tab B (Port)'!$I$1
Name Contractor4: 'Bid Tab A (FAA)'!$K$1
Name Contractor4: 'Bid Tab B (Port)'!$K$1
Name Contractor5: 'Bid Tab A (FAA)'!$M$1
Name Contractor5: 'Bid Tab B (Port)'!$M$1
Name Contractor6: 'Bid Tab A (FAA)'!$O$1
Name Contractor6: 'Bid Tab B (Port)'!$O$1
Name Contractor7: 'Bid Tab A (FAA)'!#REF!
Name Contractor7: 'Bid Tab B (Port)'!#REF!
Name Contractor8: 'Bid Tab A (FAA)'!#REF!
Name Contractor8: 'Bid Tab B (Port)'!#REF!
Name EngineerEstimate: 'Bid Tab A (FAA)'!$Q$1
Name EngineerEstimate: 'Bid Tab B (Port)'!$Q$1

Sheet Bid Item List A (FAA)
A1: Acre
A2: CY
A3: Each
A4: FT
A5: Gal
A6: Hour
A7: LB
A8: LF
A9: LS
A10: Mile
A11: SF
A12: SY
... A16: TAXIWAY B CENTER AND EXITS REHABILITATION
A19: Item No. | B19: Item Description | C19: Estimated Quantity | D19: Units | E19: Unit Price | F19: Total Price
A20: 0001 | B20: Mobilization, Cleanup, and Demobilization (Section 012200) | C20: 1 | D20: LS
A21: 0002 | B21: Sweeper (Section 012200) | C21: 1 | D21: LS
A22: 0003 | B22: Security Control Monitoring (Section 012200) | C22: 1 | D22: LS
A23: 0004 | B23: Traffic Control (Section 012200) | C23: 1 | D23: LS
A24: 0005 | B24: Escort (Section 012200) | C24: 1 | D24: LS
A25: 0006 | B25: Construction Access (Section 015713) | C25: 2 | D25: Each
A26: 0007 | B26: Jet Blast Control Material (Section 015713) | C26: 2.5 | D26: Acre
A27: 0008 | B27: Inlet Protection (Section 015713) | C27: 85 | D27: Each
A28: 0009 | B28: Ditch Protection/Check Dams (Section 015713) | C28: 12 | D28: Each
A29: 0010 | B29: Wattles (Section 015713) | C29: 1000 | D29: LF
A30: 0011 | B30: Construction Survey (Item GP-50) | C30: 1 | D30: LS
A31: 0012 | B31: PCC Pavement Removal - 3" Depth (Item P-101) | C31: 375 | D31: SY
... A91: 0072 | B91: Removal of Existing Storm Pipe, Manholes, and Inlets (Section 312300) | C91: 1 | D91: LS
A92: 0073 | B92: Connection to Existing Storm Drainage System (Section 312300) | D92: Each
A93: 0074 | B93: Existing Manhole Adjustment to Grade (Section 312300) | D93: Each
A94: 0075 | B94: Existing Catch Basin Adjustment to Grade (Section 312300) | D94: Each
A95: 0076 | B95: Existing Electrical Vault Adjustment to Grade (Section 312300) | C95: 2 | D95: Each
A96: 0077 | B96: 12-Inch Ductile Iron (Force Main) Pipe (Section 334100) | D96: LF
A97: 0078 | B97: 20-Inch Ductile Iron (Force Main) Pipe (Section 334100) | D97: LF
A98: 0079 | B98: Riprap (Section 334100) | D98: CY
A99: 0080 | B99: Stormwater Pump Station, Electrical Equipment Installation (Section 334213) | C99: 1 | D99: LS
A100: 0081 | B100: Stormwater Valve Vault (Section 334213) | C100: 1 | D100: LS
A101: 0082 | B101: Install PF LED Taxiway Centerline Light with PF Base Can, CF Transformer in New AC (Section 344300) | C101: 22 | D101: Each
A102: 0083 | B102: Install PF LED Taxiway Centerline Light on Existing Base Can with CF Isolation Transformer (Section 344300) | C102: 9 | D102: Each
A103: 0084 | B103: Adjust Existing Elevated Runway Threshold Light (Section 344301) | C103: 8 | D103: Each
A104: 0085 | B104: Adjust Existing In-Pavement Runway Edge Light (Section 344301) | C104: 8 | D104: Each
...

Sheet Bid Item List B (Port)
A1: Acre
A2: CY
A3: Each
A4: FT
A5: Gal
A6: Hour
A7: LB
A8: LF
A9: LS
A10: Mile
A11: SF
A12: SY
... A16: TAXIWAY B CENTER AND EXITS REHABILITATION
A19: Item No. | B19: Item Description | C19: Estimated Quantity | D19: Units | E19: Unit Price | F19: Total Price
A20: 0001 | B20: Wildlife Access Road, Asphalt Grindings (Section 012200) | C20: 200 | D20: CY
A21: 0002 | B21: Heat Shrink for 5kV L-823 Primary Connector (Item L-108) | C21: 435 | D21: Each
A22: 0003 | B22: 1-Inch IMC in Existing AC (Item L-110) | C22: 25 | D22: LF
A23: 0004 | B23: 3-Inch Diameter Brass Marker (Section 260553) | C23: 3 | D23: Each
B24: Total Amount Bid Schedule B | F24: $___________
B25: Total Amount Bid Schedules A and B (Basis of Award) | F25: $___________

Sheet Bid Tab A (FAA)
A1: ='Bid Item List B (Port)'!$A$15 -> PORTLAND INTERNATIONAL AIRPORT | E1: Goodfella Bros., Inc. | G1: K&E Excavating, Inc. | I1: Kerr Contractors Oregon, Inc. | K1: Kodiak Pacific Construction | M1: Nutter Corp. | O1: Wildish Standard Paving Co. | Q1: Engineer's Estimate
A2: ='Bid Item List B (Port)'!$A$16 -> TAXIWAY B CENTER AND EXITS REHABILITATION
A3: ='Bid Item List B (Port)'!$A$17 -> 0
A4: EAN 2015D147
A5: Solicitation No. 2016-6920
A6: =TODAY() -> 42754
A7: Item No. | B7: Item Description | C7: Estimated Quantity | D7: Units | E7: Unit Price | F7: Total Price | G7: Unit Price | H7: Total Price | I7: Unit Price | J7: Total Price | K7: Unit Price | L7: Total Price | M7: Unit Price | N7: Total Price | O7: Unit Price | P7: Total Price | Q7: Unit Price | R7: Total Price
A8: ='Bid Item List A (FAA)'!$A20 -> 0001 | B8: ='Bid Item List A (FAA)'!B20 -> Mobilization, Cleanup, and Demobilization (Section 012200) | C8: ='Bid Item List A (FAA)'!C20 -> 1 | D8: ='Bid Item List A (FAA)'!D20 -> LS | E8: 1907000 | F8: =C8*E8 -> 1907000 | G8: 1800000 | H8: =C8*G8 -> 1800000 | I8: 1825000 | J8: =C8*I8 -> 1825000 | K8: 900000 | L8: =C8*K8 -> 900000 | M8: 1820000 | N8: =C8*M8 -> 1820000 | O8: 475000 | P8: =C8*O8 -> 475000 | Q8: 1310268 | R8: =C8*Q8 -> 1310268
A9: ='Bid Item List A (FAA)'!A21 -> 0002 | B9: ='Bid Item List A (FAA)'!B21 -> Sweeper (Section 012200) | C9: ='Bid Item List A (FAA)'!C21 -> 1 | D9: ='Bid Item List A (FAA)'!D21 -> LS | E9: 130000 | F9: =C9*E9 -> 130000 | G9: 260000 | H9: =C9*G9 -> 260000 | I9: 225000 | J9: =C9*I9 -> 225000 | K9: 265000 | L9: =C9*K9 -> 265000 | M9: 400000 | N9: =C9*M9 -> 400000 | O9: 600000 | P9: =C9*O9 -> 600000 | Q9: 150000 | R9: =C9*Q9 -> 150000
A10: ='Bid Item List A (FAA)'!A22 -> 0003 | B10: ='Bid Item List A (FAA)'!B22 -> Security Control Monitoring (Section 012200) | C10: ='Bid Item List A (FAA)'!C22 -> 1 | D10: ='Bid Item List A (FAA)'!D22 -> LS | E10: 65000 | F10: =C10*E10 -> 65000 | G10: 25000 | H10: =C10*G10 -> 25000 | I10: 100000 | J10: =C10*I10 -> 100000 | K10: 103000 | L10: =C10*K10 -> 103000 | M10: 115000 | N10: =C10*M10 -> 115000 | O10: 340000 | P10: =C10*O10 -> 340000 | Q10: 30000 | R10: =C10*Q10 -> 30000
A11: ='Bid Item List A (FAA)'!A23 -> 0004 | B11: ='Bid Item List A (FAA)'!B23 -> Traffic Control (Section 012200) | C11: ='Bid Item List A (FAA)'!C23 -> 1 | D11: ='Bid Item List A (FAA)'!D23 -> LS | E11: 75000 | F11: =C11*E11 -> 75000 | G11: 300000 | H11: =C11*G11 -> 300000 | I11: 251566.5 | J11: =C11*I11 -> 251566.5 | K11: 420000 | L11: =C11*K11 -> 420000 | M11: 100000 | N11: =C11*M11 -> 100000 | O11: 500000 | P11: =C11*O11 -> 500000 | Q11: 175000 | R11: =C11*Q11 -> 175000
A12: ='Bid Item List A (FAA)'!$A24 -> 0005 | B12: ='Bid Item List A (FAA)'!B24 -> Escort (Section 012200) | C12: ='Bid Item List A (FAA)'!C24 -> 1 | D12: ='Bid Item List A (FAA)'!D24 -> LS | E12: 75000 | F12: =C12*E12 -> 75000 | G12: 250000 | H12: =C12*G12 -> 250000 | I12: 250000 | J12: =C12*I12 -> 250000 | K12: 278000 | L12: =C12*K12 -> 278000 | M12: 306000 | N12: =C12*M12 -> 306000 | O12: 1400000 | P12: =C12*O12 -> 1400000 | Q12: 100000 | R12: =C12*Q12 -> 100000
A13: ='Bid Item List A (FAA)'!A25 -> 0006 | B13: ='Bid Item List A (FAA)'!B25 -> Construction Access (Section 015713) | C13: ='Bid Item List A (FAA)'!C25 -> 2 | D13: ='Bid Item List A (FAA)'!D25 -> Each | E13: 10000 | F13: =C13*E13 -> 20000 | G13: 3500 | H13: =C13*G13 -> 7000 | I13: 2500 | J13: =C13*I13 -> 5000 | K13: 1330 | L13: =C13*K13 -> 2660 | M13: 5000 | N13: =C13*M13 -> 10000 | O13: 7000 | P13: =C13*O13 -> 14000 | Q13: 2500 | R13: =C13*Q13 -> 5000
A14: ='Bid Item List A (FAA)'!A26 -> 0007 | B14: ='Bid Item List A (FAA)'!B26 -> Jet Blast Control Material (Section 015713) | C14: ='Bid Item List A (FAA)'!C26 -> 2.5 | D14: ='Bid Item List A (FAA)'!D26 -> Acre | E14: 5150 | F14: =C14*E14 -> 12875 | G14: 3500 | H14: =C14*G14 -> 8750 | I14: 3050 | J14: =C14*I14 -> 7625 | K14: 3200 | L14: =C14*K14 -> 8000 | M14: 3300 | N14: =C14*M14 -> 8250 | O14: 4000 | P14: =C14*O14 -> 10000 | Q14: 3600 | R14: =C14*Q14 -> 9000
A15: ='Bid Item List A (FAA)'!A27 -> 0008 | B15: ='Bid Item List A (FAA)'!B27 -> Inlet Protection (Section 015713) | C15: ='Bid Item List A (FAA)'!C27 -> 85 | D15: ='Bid Item List A (FAA)'!D27 -> Each | E15: 150 | F15: =C15*E15 -> 12750 | G15: 85 | H15: =C15*G15 -> 7225 | I15: 65 | J15: =C15*I15 -> 5525 | K15: 103 | L15: =C15*K15 -> 8755 | M15: 70 | N15: =C15*M15 -> 5950 | O15: 125 | P15: =C15*O15 -> 10625 | Q15: 80 | R15: =C15*Q15 -> 6800
A16: ='Bid Item List A (FAA)'!$A28 -> 0009 | B16: ='Bid Item List A (FAA)'!B28 -> Ditch Protection/Check Dams (Section 015713) | C16: ='Bid Item List A (FAA)'!C28 -> 12 | D16: ='Bid Item List A (FAA)'!D28 -> Each | E16: 500 | F16: =C16*E16 -> 6000 | G16: 100 | H16: =C16*G16 -> 1200 | I16: 70 | J16: =C16*I16 -> 840 | K16: 165 | L16: =C16*K16 -> 1980 | M16: 130 | N16: =C16*M16 -> 1560 | O16: 150 | P16: =C16*O16 -> 1800 | Q16: 175 | R16: =C16*Q16 -> 2100
A17: ='Bid Item List A (FAA)'!A29 -> 0010 | B17: ='Bid Item List A (FAA)'!B29 -> Wattles (Section 015713) | C17: ='Bid Item List A (FAA)'!C29 -> 1000 | D17: ='Bid Item List A (FAA)'!D29 -> LF | E17: 5 | F17: =C17*E17 -> 5000 | G17: 3 | H17: =C17*G17 -> 3000 | I17: 2.75 | J17: =C17*I17 -> 2750 | K17: 2.85 | L17: =C17*K17 -> 2850 | M17: 4 | N17: =C17*M17 -> 4000 | O17: 4 | P17: =C17*O17 -> 4000 | Q17: 3.5 | R17: =C17*Q17 -> 3500
A18: ='Bid Item List A (FAA)'!A30 -> 0011 | B18: ='Bid Item List A (FAA)'!B30 -> Construction Survey (Item GP-50) | C18: ='Bid Item List A (FAA)'!C30 -> 1 | D18: ='Bid Item List A (FAA)'!D30 -> LS | E18: 400000 | F18: =C18*E18 -> 400000 | G18: 240000 | H18: =C18*G18 -> 240000 | I18: 200000 | J18: =C18*I18 -> 200000 | K18: 447000 | L18: =C18*K18 -> 447000 | M18: 400000.47 | N18: =C18*M18 -> 400000.47 | O18: 250000 | P18: =C18*O18 -> 250000 | Q18: 115000 | R18: =C18*Q18 -> 115000
A19: ='Bid Item List A (FAA)'!A31 -> 0012 | B19: ='Bid Item List A (FAA)'!B31 -> PCC Pavement Removal - 3" Depth (Item P-101) | C19: ='Bid Item List A (FAA)'!C31 -> 375 | D19: ='Bid Item List A (FAA)'!D31 -> SY | E19: 20 | F19: =C19*E19 -> 7500 | G19: 11 | H19: =C19*G19 -> 4125 | I19: 2.75 | J19: =C19*I19 -> 1031.25 | K19: 6.9 | L19: =C19*K19 -> 2587.5 | M19: 11 | N19: =C19*M19 -> 4125 | O19: 30 | P19: =C19*O19 -> 11250 | Q19: 11.25 | R19: =C19*Q19 -> 4218.75
A20: ='Bid Item List A (FAA)'!$A32 -> 0013 | B20: ='Bid Item List A (FAA)'!B32 -> PCC Pavement Removal - 6" Depth (Item P-101) | C20: ='Bid Item List A (FAA)'!C32 -> 950 | D20: ='Bid Item List A (FAA)'!D32 -> SY | E20: 15 | F20: =C20*E20 -> 14250 | G20: 10 | H20: =C20*G20 -> 9500 | I20: 6.5 | J20: =C20*I20 -> 6175 | K20: 11 | L20: =C20*K20 -> 10450 | M20: 13 | N20: =C20*M20 -> 12350 | O20: 30 | P20: =C20*O20 -> 28500 | Q20: 22.5 | R20: =C20*Q20 -> 21375
A21: ='Bid Item List A (FAA)'!A33 -> 0014 | B21: ='Bid Item List A (FAA)'!B33 -> Asphalt Pavement Removal - 3" Depth (Item P-101) | C21: ='Bid Item List A (FAA)'!C33 -> 19700 | D21: ='Bid Item List A (FAA)'!D33 -> SY | E21: 4 | F21: =C21*E21 -> 78800 | G21: 2 | H21: =C21*G21 -> 39400 | I21: 2.35 | J21: =C21*I21 -> 46295 | K21: 2 | L21: =C21*K21 -> 39400 | M21: 3 | N21: =C21*M21 -> 59100 | O21: 3 | P21: =C21*O21 -> 59100 | Q21: 1.7 | R21: =C21*Q21 -> 33490
A22: ='Bid Item List A (FAA)'!A34 -> 0015 | B22: ='Bid Item List A (FAA)'!B34 -> Asphalt Pavement Removal - 5" Depth (Item P-101) | C22: ='Bid Item List A (FAA)'!C34 -> 2100 | D22: ='Bid Item List A (FAA)'!D34 -> SY | E22: 5 | F22: =C22*E22 -> 10500 | G22: 3.5 | H22: =C22*G22 -> 7350 | I22: 4 | J22: =C22*I22 -> 8400 | K22: 4.75 | L22: =C22*K22 -> 9975 | M22: 6.5 | N22: =C22*M22 -> 13650 | O22: 4 | P22: =C22*O22 -> 8400 | Q22: 2.8 | R22: =C22*Q22 -> 5880
A23: ='Bid Item List A (FAA)'!A35 -> 0016 | B23: ='Bid Item List A (FAA)'!B35 -> Asphalt Pavement Removal - 7.5" Depth (Item P-101) | C23: ='Bid Item List A (FAA)'!C35 -> 2600 | D23: ='Bid Item List A (FAA)'!D35 -> SY | E23: 7 | F23: =C23*E23 -> 18200 | G23: 4.85 | H23: =C23*G23 -> 12610 | I23: 6.15 | J23: =C23*I23 -> 15990 | K23: 2.9 | L23: =C23*K23 -> 7540 | M23: 7 | N23: =C23*M23 -> 18200 | O23: 6 | P23: =C23*O23 -> 15600 | Q23: 4.2 | R23: =C23*Q23 -> 10920
A24: ='Bid Item List A (FAA)'!$A36 -> 0017 | B24: ='Bid Item List A (FAA)'!B36 -> Asphalt Pavement Removal - 12" Depth (Item P-101) | C24: ='Bid Item List A (FAA)'!C36 -> 8700 | D24: ='Bid Item List A (FAA)'!D36 -> SY | E24: 10 | F24: =C24*E24 -> 87000 | G24: 9.5 | H24: =C24*G24 -> 82650 | I24: 9.5 | J24: =C24*I24 -> 82650 | K24: 7 | L24: =C24*K24 -> 60900 | M24: 8 | N24: =C24*M24 -> 69600 | O24: 8 | P24: =C24*O24 -> 69600 | Q24: 6.7 | R24: =C24*Q24 -> 58290
A25: ='Bid Item List A (FAA)'!$A37 -> 0018 | B25: ='Bid Item List A (FAA)'!B37 -> Asphalt Pavement Removal - 14" Depth (Item P-101) | C25: ='Bid Item List A (FAA)'!C37 -> 950 | D25: ='Bid Item List A (FAA)'!D37 -> SY | E25: 11 | F25: =C25*E25 -> 10450 | G25: 12.5 | H25: =C25*G25 -> 11875 | I25: 11 | J25: =C25*I25 -> 10450 | K25: 8.1 | L25: =C25*K25 -> 7695 | M25: 16 | N25: =C25*M25 -> 15200 | O25: 10 | P25: =C25*O25 -> 9500 | Q25: 7.8 | R25: =C25*Q25 -> 7410
A26: ='Bid Item List A (FAA)'!A38 -> 0019 | B26: ='Bid Item List A (FAA)'!B38 -> Asphalt Pavement Removal - 16" Depth (Item P-101) | C26: ='Bid Item List A (FAA)'!C38 -> 15200 | D26: ='Bid Item List A (FAA)'!D38 -> SY | E26: 13 | F26: =C26*E26 -> 197600 | G26: 10.75 | H26: =C26*G26 -> 163400 | I26: 12.5 | J26: =C26*I26 -> 190000 | K26: 9.3 | L26: =C26*K26 -> 141360 | M26: 13 | N26: =C26*M26 -> 197600 | O26: 11 | P26: =C26*O26 -> 167200 | Q26: 8.9 | R26: =C26*Q26 -> 135280
A27: ='Bid Item List A (FAA)'!A39 -> 0020 | B27: ='Bid Item List A (FAA)'!B39 -> Asphalt Pavement Removal - 20" Depth (Item P-101) | C27: ='Bid Item List A (FAA)'!C39 -> 23600 | D27: ='Bid Item List A (FAA)'!D39 -> SY | E27: 14 | F27: =C27*E27 -> 330400 | G27: 12.5 | H27: =C27*G27 -> 295000 | I27: 15.5 | J27: =C27*I27 -> 365800 | K27: 10 | L27: =C27*K27 -> 236000 | M27: 16 | N27: =C27*M27 -> 377600 | O27: 12 | P27: =C27*O27 -> 283200 | Q27: 11.15 | R27: =C27*Q27 -> 263140
A28: ='Bid Item List A (FAA)'!A40 -> 0021 | B28: ='Bid Item List A (FAA)'!B40 -> Asphalt Pavement Removal - 22" Depth (Item P-101) | C28: ='Bid Item List A (FAA)'!C40 -> 6100 | D28: ='Bid Item List A (FAA)'!D40 -> SY | E28: 20 | F28: =C28*E28 -> 122000 | G28: 13 | H28: =C28*G28 -> 79300 | I28: 17.25 | J28: =C28*I28 -> 105225 | K28: 12.8 | L28: =C28*K28 -> 78080 | M28: 16 | N28: =C28*M28 -> 97600 | O28: 13 | P28: =C28*O28 -> 79300 | Q28: 12.25 | R28: =C28*Q28 -> 74725
A29: ='Bid Item List A (FAA)'!$A41 -> 0022 | B29: ='Bid Item List A (FAA)'!B41 -> Asphalt Pavement Removal - 12" Depth Asphalt Grindings (Item P-101) | C29: ='Bid Item List A (FAA)'!C41 -> 375 | D29: ='Bid Item List A (FAA)'!D41 -> SY | E29: 25 | F29: =C29*E29 -> 9375 | G29: 11 | H29: =C29*G29 -> 4125 | I29: 6.5 | J29: =C29*I29 -> 2437.5 | K29: 6.2 | L29: =C29*K29 -> 2325 | M29: 5 | N29: =C29*M29 -> 1875 | O29: 6 | P29: =C29*O29 -> 2250 | Q29: 6.5 | R29: =C29*Q29 -> 2437.5
A30: ='Bid Item List A (FAA)'!A42 -> 0023 | B30: ='Bid Item List A (FAA)'!B42 -> Joint and Crack Repair (Item P-101) | C30: ='Bid Item List A (FAA)'!C42 -> 1500 | D30: ='Bid Item List A (FAA)'!D42 -> LF | E30: 12 | F30: =C30*E30 -> 18000 | G30: 4.5 | H30: =C30*G30 -> 6750 | I30: 4 | J30: =C30*I30 -> 6000 | K30: 5.1 | L30: =C30*K30 -> 7650 | M30: 4 | N30: =C30*M30 -> 6000 | O30: 5 | P30: =C30*O30 -> 7500 | Q30: 5 | R30: =C30*Q30 -> 7500
A31: ='Bid Item List A (FAA)'!A43 -> 0024 | B31: ='Bid Item List A (FAA)'!B43 -> Cold Milling - 4 Inch Maximum Depth (Item P-101) | C31: ='Bid Item List A (FAA)'!C43 -> 5500 | D31: ='Bid Item List A (FAA)'!D43 -> SY | E31: 5 | F31: =C31*E31 -> 27500 | G31: 4.35 | H31: =C31*G31 -> 23925 | I31: 3.75 | J31: =C31*I31 -> 20625 | K31: 4.7 | L31: =C31*K31 -> 25850 | M31: 5.5 | N31: =C31*M31 -> 30250 | O31: 7 | P31: =C31*O31 -> 38500 | Q31: 5.5 | R31: =C31*Q31 -> 30250
A32: ='Bid Item List A (FAA)'!A44 -> 0025 | B32: ='Bid Item List A (FAA)'!B44 -> Unclassified Excavation (P-152) | C32: ='Bid Item List A (FAA)'!C44 -> 37500 | D32: ='Bid Item List A (FAA)'!D44 -> CY | E32: 41 | F32: =C32*E32 -> 1537500 | G32: 17 | H32: =C32*G32 -> 637500 | I32: 17.5 | J32: =C32*I32 -> 656250 | K32: 31 | L32: =C32*K32 -> 1162500 | M32: 20 | N32: =C32*M32 -> 750000 | O32: 10 | P32: =C32*O32 -> 375000 | Q32: 15 | R32: =C32*Q32 -> 562500
A33: ='Bid Item List A (FAA)'!$A45 -> 0026 | B33: ='Bid Item List A (FAA)'!B45 -> Unsuitable Excavation (Item P-152) | C33: ='Bid Item List A (FAA)'!C45 -> 1000 | D33: ='Bid Item List A (FAA)'!D45 -> CY | E33: 90 | F33: =C33*E33 -> 90000 | G33: 57 | H33: =C33*G33 -> 57000 | I33: 58 | J33: =C33*I33 -> 58000 | K33: 38 | L33: =C33*K33 -> 38000 | M33: 22 | N33: =C33*M33 -> 22000 | O33: 60 | P33: =C33*O33 -> 60000 | Q33: 50 | R33: =C33*Q33 -> 50000
A34: ='Bid Item List A (FAA)'!A46 -> 0027 | B34: ='Bid Item List A (FAA)'!B46 -> Geotextile (Item P-152) | C34: ='Bid Item List A (FAA)'!C46 -> 87400 | D34: ='Bid Item List A (FAA)'!D46 -> SY | E34: 1.25 | F34: =C34*E34 -> 109250 | G34: 0.7 | H34: =C34*G34 -> 61180 | I34: 0.8 | J34: =C34*I34 -> 69920 | K34: 0.8 | L34: =C34*K34 -> 69920 | M34: 0.8 | N34: =C34*M34 -> 69920 | O34: 3 | P34: =C34*O34 -> 262200 | Q34: 1.1 | R34: =C34*Q34 -> 96140
A35: ='Bid Item List A (FAA)'!A47 -> 0028 | B35: ='Bid Item List A (FAA)'!B47 -> Controlled Low-Strength Material (CLSM) (Item P-153) | C35: ='Bid Item List A (FAA)'!C47 -> 1500 | D35: ='Bid Item List A (FAA)'!D47 -> CY | E35: 145 | F35: =C35*E35 -> 217500 | G35: 115 | H35: =C35*G35 -> 172500 | I35: 105 | J35: =C35*I35 -> 157500 | K35: 200 | L35: =C35*K35 -> 300000 | M35: 120 | N35: =C35*M35 -> 180000 | O35: 50 | P35: =C35*O35 -> 75000 | Q35: 100 | R35: =C35*Q35 -> 150000
A36: ='Bid Item List A (FAA)'!A48 -> 0029 | B36: ='Bid Item List A (FAA)'!B48 -> Subbase Course (Item P-154) | C36: ='Bid Item List A (FAA)'!C48 -> 6900 | D36: ='Bid Item List A (FAA)'!D48 -> CY | E36: 36 | F36: =C36*E36 -> 248400 | G36: 35 | H36: =C36*G36 -> 241500 | I36: 25 | J36: =C36*I36 -> 172500 | K36: 36 | L36: =C36*K36 -> 248400 | M36: 20 | N36: =C36*M36 -> 138000 | O36: 6 | P36: =C36*O36 -> 41400 | Q36: 18 | R36: =C36*Q36 -> 124200
A37: ='Bid Item List A (FAA)'!$A49 -> 0030 | B37: ='Bid Item List A (FAA)'!B49 -> Silt Fence (Item P-156) | C37: ='Bid Item List A (FAA)'!C49 -> 5100 | D37: ='Bid Item List A (FAA)'!D49 -> LF | E37: 3 | F37: =C37*E37 -> 15300 | G37: 2 | H37: =C37*G37 -> 10200 | I37: 2 | J37: =C37*I37 -> 10200 | K37: 2 | L37: =C37*K37 -> 10200 | M37: 3 | N37: =C37*M37 -> 15300 | O37: 4 | P37: =C37*O37 -> 20400 | Q37: 2.5 | R37: =C37*Q37 -> 12750
A38: ='Bid Item List A (FAA)'!A50 -> 0031 | B38: ='Bid Item List A (FAA)'!B50 -> Crushed Aggregate Base Course (Item P-209) | C38: ='Bid Item List A (FAA)'!C50 -> 17800 | D38: ='Bid Item List A (FAA)'!D50 -> CY | E38: 55 | F38: =C38*E38 -> 979000 | G38: 46 | H38: =C38*G38 -> 818800 | I38: 60 | J38: =C38*I38 -> 1068000 | K38: 45 | L38: =C38*K38 -> 801000 | M38: 45 | N38: =C38*M38 -> 801000 | O38: 48 | P38: =C38*O38 -> 854400 | Q38: 42.5 | R38: =C38*Q38 -> 756500
A39: ='Bid Item List A (FAA)'!A51 -> 0032 | B39: ='Bid Item List A (FAA)'!B51 -> Hot Mix Asphalt (HMA) Pavement (Item P-401) | C39: ='Bid Item List A (FAA)'!C51 -> 11300 | D39: ='Bid Item List A (FAA)'!D51 -> Ton | E39: 85 | F39: =C39*E39 -> 960500 | G39: 85 | H39: =C39*G39 -> 960500 | I39: 80 | J39: =C39*I39 -> 904000 | K39: 82 | L39: =C39*K39 -> 926600 | M39: 85 | N39: =C39*M39 -> 960500 | O39: 88 | P39: =C39*O39 -> 994400 | Q39: 98 | R39: =C39*Q39 -> 1107400
A40: ='Bid Item List A (FAA)'!A52 -> 0033 | B40: ='Bid Item List A (FAA)'!B52 -> Hot Mix Asphalt (HMA) Pavement Base Course (Item P-403) | C40: ='Bid Item List A (FAA)'!C52 -> 22800 | D40: ='Bid Item List A (FAA)'!D52 -> Ton | E40: 81 | F40: =C40*E40 -> 1846800 | G40: 85 | H40: =C40*G40 -> 1938000 | I40: 80 | J40: =C40*I40 -> 1824000 | K40: 82 | L40: =C40*K40 -> 1869600 | M40: 85 | N40: =C40*M40 -> 1938000 | O40: 85 | P40: =C40*O40 -> 1938000 | Q40: 90 | R40: =C40*Q40 -> 2052000
...

Sheet Bid Tab B (Port)
A1: ='Bid Item List B (Port)'!$A$15 -> PORTLAND INTERNATIONAL AIRPORT | E1: ='Bid Tab A (FAA)'!Contractor1 -> Goodfella Bros., Inc. | G1: ='Bid Tab A (FAA)'!Contractor2 -> K&E Excavating, Inc. | I1: ='Bid Tab A (FAA)'!Contractor3 -> Kerr Contractors Oregon, Inc. | K1: ='Bid Tab A (FAA)'!Contractor4 -> Kodiak Pacific Construction | M1: ='Bid Tab A (FAA)'!Contractor5 -> Nutter Corp. | O1: ='Bid Tab A (FAA)'!Contractor6 -> Wildish Standard Paving Co. | Q1: ='Bid Tab A (FAA)'!EngineerEstimate -> Engineer's Estimate
A2: ='Bid Item List B (Port)'!$A$16 -> TAXIWAY B CENTER AND EXITS REHABILITATION
A3: ='Bid Item List B (Port)'!$A$17 -> 0
A4: ='Bid Tab A (FAA)'!A4:D4 -> EAN 2015D147
A5: ='Bid Tab A (FAA)'!A5:D5 -> Solicitation No. 2016-6920
A6: =TODAY() -> 42754
A7: Item No. | B7: Item Description | C7: Estimated Quantity | D7: Units | E7: Unit Price | F7: Total Price | G7: Unit Price | H7: Total Price | I7: Unit Price | J7: Total Price | K7: Unit Price | L7: Total Price | M7: Unit Price | N7: Total Price | O7: Unit Price | P7: Total Price | Q7: Unit Price | R7: Total Price
A8: ='Bid Item List B (Port)'!A20 -> 0001 | B8: ='Bid Item List B (Port)'!B20 -> Wildlife Access Road, Asphalt Grindings (Section 012200) | C8: ='Bid Item List B (Port)'!C20 -> 200 | D8: ='Bid Item List B (Port)'!D20 -> CY | E8: 100 | F8: =C8*E8 -> 20000 | G8: 12 | H8: =C8*G8 -> 2400 | I8: 15 | J8: =C8*I8 -> 3000 | K8: 0 | L8: =C8*K8 -> 0 | M8: 10 | N8: =C8*M8 -> 2000 | O8: 25 | P8: =C8*O8 -> 5000 | Q8: 35 | R8: =C8*Q8 -> 7000
A9: ='Bid Item List B (Port)'!A21 -> 0002 | B9: ='Bid Item List B (Port)'!B21 -> Heat Shrink for 5kV L-823 Primary Connector (Item L-108) | C9: ='Bid Item List B (Port)'!C21 -> 435 | D9: ='Bid Item List B (Port)'!D21 -> Each | E9: 5 | F9: =C9*E9 -> 2175 | G9: 1 | H9: =C9*G9 -> 435 | I9: 1 | J9: =C9*I9 -> 435 | K9: 0 | L9: =C9*K9 -> 0 | M9: 1 | N9: =C9*M9 -> 435 | O9: 1 | P9: =C9*O9 -> 435 | Q9: 1.25 | R9: =C9*Q9 -> 543.75
A10: ='Bid Item List B (Port)'!A22 -> 0003 | B10: ='Bid Item List B (Port)'!B22 -> 1-Inch IMC in Existing AC (Item L-110) | C10: ='Bid Item List B (Port)'!C22 -> 25 | D10: ='Bid Item List B (Port)'!D22 -> LF | E10: 5 | F10: =C10*E10 -> 125 | G10: 0.7 | H10: =C10*G10 -> 17.5 | I10: 0.75 | J10: =C10*I10 -> 18.75 | K10: 0 | L10: =C10*K10 -> 0 | M10: 1 | N10: =C10*M10 -> 25 | O10: 1 | P10: =C10*O10 -> 25 | Q10: 3.5 | R10: =C10*Q10 -> 87.5
A11: ='Bid Item List B (Port)'!A23 -> 0004 | B11: ='Bid Item List B (Port)'!B23 -> 3-Inch Diameter Brass Marker (Section 260553) | C11: ='Bid Item List B (Port)'!C23 -> 3 | D11: ='Bid Item List B (Port)'!D23 -> Each | E11: 160 | F11: =C11*E11 -> 480 | G11: 160 | H11: =C11*G11 -> 480 | I11: 155 | J11: =C11*I11 -> 465 | K11: 0 | L11: =C11*K11 -> 0 | M11: 160 | N11: =C11*M11 -> 480 | O11: 200 | P11: =C11*O11 -> 600 | Q11: 200 | R11: =C11*Q11 -> 600
A12: ='Bid Item List B (Port)'!#REF! -> #REF! | B12: ='Bid Item List B (Port)'!#REF! -> #REF! | C12: ='Bid Item List B (Port)'!#REF! -> #REF! | D12: ='Bid Item List B (Port)'!#REF! -> #REF! | E12: 36 | F12: =C12*E12 -> #REF! | G12: 38 | H12: =C12*G12 -> #REF! | I12: 36 | J12: =C12*I12 -> #REF! | K12: 0 | L12: =C12*K12 -> #REF! | M12: 37 | N12: =C12*M12 -> #REF! | O12: 40 | P12: =C12*O12 -> #REF! | Q12: 30 | R12: =C12*Q12 -> #REF!
A13: ='Bid Item List B (Port)'!#REF! -> #REF! | B13: ='Bid Item List B (Port)'!#REF! -> #REF! | C13: ='Bid Item List B (Port)'!#REF! -> #REF! | D13: ='Bid Item List B (Port)'!#REF! -> #REF! | E13: 110 | F13: =C13*E13 -> #REF! | G13: 120 | H13: =C13*G13 -> #REF! | I13: 110 | J13: =C13*I13 -> #REF! | K13: 0 | L13: =C13*K13 -> #REF! | M13: 115 | N13: =C13*M13 -> #REF! | O13: 120 | P13: =C13*O13 -> #REF! | Q13: 150 | R13: =C13*Q13 -> #REF!
A14: ='Bid Item List B (Port)'!#REF! -> #REF! | B14: ='Bid Item List B (Port)'!#REF! -> #REF! | C14: ='Bid Item List B (Port)'!#REF! -> #REF! | D14: ='Bid Item List B (Port)'!#REF! -> #REF! | E14: 36 | F14: =C14*E14 -> #REF! | G14: 38 | H14: =C14*G14 -> #REF! | I14: 36 | J14: =C14*I14 -> #REF! | K14: 0 | L14: =C14*K14 -> #REF! | M14: 39 | N14: =C14*M14 -> #REF! | O14: 40 | P14: =C14*O14 -> #REF! | Q14: 65 | R14: =C14*Q14 -> #REF!
A15: ='Bid Item List B (Port)'!#REF! -> #REF! | B15: ='Bid Item List B (Port)'!#REF! -> #REF! | C15: ='Bid Item List B (Port)'!#REF! -> #REF! | D15: ='Bid Item List B (Port)'!#REF! -> #REF! | E15: 100 | F15: =C15*E15 -> #REF! | G15: 55 | H15: =C15*G15 -> #REF! | I15: 70 | J15: =C15*I15 -> #REF! | K15: 0 | L15: =C15*K15 -> #REF! | M15: 48 | N15: =C15*M15 -> #REF! | O15: 75 | P15: =C15*O15 -> #REF! | Q15: 55 | R15: =C15*Q15 -> #REF!
A16: ='Bid Item List B (Port)'!#REF! -> #REF! | B16: ='Bid Item List B (Port)'!#REF! -> #REF! | C16: ='Bid Item List B (Port)'!#REF! -> #REF! | D16: ='Bid Item List B (Port)'!#REF! -> #REF! | E16: 6600 | F16: =C16*E16 -> #REF! | G16: 7000 | H16: =C16*G16 -> #REF! | I16: 7000 | J16: =C16*I16 -> #REF! | K16: 0 | L16: =C16*K16 -> #REF! | M16: 6700 | N16: =C16*M16 -> #REF! | O16: 7000 | P16: =C16*O16 -> #REF! | Q16: 6500 | R16: =C16*Q16 -> #REF!
A17: ='Bid Item List B (Port)'!#REF! -> #REF! | B17: ='Bid Item List B (Port)'!#REF! -> #REF! | C17: ='Bid Item List B (Port)'!#REF! -> #REF! | D17: ='Bid Item List B (Port)'!#REF! -> #REF! | E17: 8200 | F17: =C17*E17 -> #REF! | G17: 8500 | H17: =C17*G17 -> #REF! | I17: 8500 | J17: =C17*I17 -> #REF! | K17: 0 | L17: =C17*K17 -> #REF! | M17: 8300 | N17: =C17*M17 -> #REF! | O17: 10000 | P17: =C17*O17 -> #REF! | Q17: 15000 | R17: =C17*Q17 -> #REF!
A18: ='Bid Item List B (Port)'!#REF! -> #REF! | B18: ='Bid Item List B (Port)'!#REF! -> #REF! | C18: ='Bid Item List B (Port)'!#REF! -> #REF! | D18: ='Bid Item List B (Port)'!#REF! -> #REF! | E18: 540 | F18: =C18*E18 -> #REF! | G18: 975 | H18: =C18*G18 -> #REF! | I18: 800 | J18: =C18*I18 -> #REF! | K18: 0 | L18: =C18*K18 -> #REF! | M18: 750 | N18: =C18*M18 -> #REF! | O18: 2000 | P18: =C18*O18 -> #REF! | Q18: 800 | R18: =C18*Q18 -> #REF!
A19: ='Bid Item List B (Port)'!#REF! -> #REF! | B19: ='Bid Item List B (Port)'!#REF! -> #REF! | C19: ='Bid Item List B (Port)'!#REF! -> #REF! | D19: ='Bid Item List B (Port)'!#REF! -> #REF! | E19: 100 | F19: =C19*E19 -> #REF! | G19: 110 | H19: =C19*G19 -> #REF! | I19: 100 | J19: =C19*I19 -> #REF! | K19: 0 | L19: =C19*K19 -> #REF! | M19: 100 | N19: =C19*M19 -> #REF! | O19: 300 | P19: =C19*O19 -> #REF! | Q19: 150 | R19: =C19*Q19 -> #REF!
A20: ='Bid Item List B (Port)'!#REF! -> #REF! | B20: ='Bid Item List B (Port)'!#REF! -> #REF! | C20: ='Bid Item List B (Port)'!#REF! -> #REF! | D20: ='Bid Item List B (Port)'!#REF! -> #REF! | E20: 300 | F20: =C20*E20 -> #REF! | G20: 270 | H20: =C20*G20 -> #REF! | I20: 300 | J20: =C20*I20 -> #REF! | K20: 0 | L20: =C20*K20 -> #REF! | M20: 315 | N20: =C20*M20 -> #REF! | O20: 350 | P20: =C20*O20 -> #REF! | Q20: 275 | R20: =C20*Q20 -> #REF!
A21: ='Bid Item List B (Port)'!#REF! -> #REF! | B21: ='Bid Item List B (Port)'!#REF! -> #REF! | C21: ='Bid Item List B (Port)'!#REF! -> #REF! | D21: ='Bid Item List B (Port)'!#REF! -> #REF! | E21: 1450 | F21: =C21*E21 -> #REF! | G21: 1600 | H21: =C21*G21 -> #REF! | I21: 2000 | J21: =C21*I21 -> #REF! | K21: 0 | L21: =C21*K21 -> #REF! | M21: 1500 | N21: =C21*M21 -> #REF! | O21: 1700 | P21: =C21*O21 -> #REF! | Q21: 1250 | R21: =C21*Q21 -> #REF!
A22: ='Bid Item List B (Port)'!#REF! -> #REF! | B22: ='Bid Item List B (Port)'!#REF! -> #REF! | C22: ='Bid Item List B (Port)'!#REF! -> #REF! | D22: ='Bid Item List B (Port)'!#REF! -> #REF! | E22: 24000 | F22: =C22*E22 -> #REF! | G22: 90000 | H22: =C22*G22 -> #REF! | I22: 55000 | J22: =C22*I22 -> #REF! | K22: 0 | L22: =C22*K22 -> #REF! | M22: 38000 | N22: =C22*M22 -> #REF! | O22: 50000 | P22: =C22*O22 -> #REF! | Q22: 50000 | R22: =C22*Q22 -> #REF!
A23: ='Bid Item List B (Port)'!#REF! -> #REF! | B23: ='Bid Item List B (Port)'!#REF! -> #REF! | C23: ='Bid Item List B (Port)'!#REF! -> #REF! | D23: ='Bid Item List B (Port)'!#REF! -> #REF! | E23: 200 | F23: =C23*E23 -> #REF! | G23: 185 | H23: =C23*G23 -> #REF! | I23: 175 | J23: =C23*I23 -> #REF! | K23: 0 | L23: =C23*K23 -> #REF! | M23: 185 | N23: =C23*M23 -> #REF! | O23: 200 | P23: =C23*O23 -> #REF! | Q23: 100 | R23: =C23*Q23 -> #REF!
B24: Total Amount Bid Schedule B | F24: =SUM(F8:F23) -> #REF! | H24: =SUM(H8:H23) -> #REF! | J24: =SUM(J8:J23) -> #REF! | L24: =SUM(L8:L23) -> #REF! | N24: =SUM(N8:N23) -> #REF! | P24: =SUM(P8:P23) -> #REF! | R24: =SUM(R8:R23) -> #REF!
B25: Total Amount Bid Schedules A and B (Basis of Award) | F25: ='Bid Tab A (FAA)'!F141+'Bid Tab B (Port)'!F24 -> #REF! | H25: ='Bid Tab A (FAA)'!H141+'Bid Tab B (Port)'!H24 -> #REF! | J25: ='Bid Tab A (FAA)'!J141+'Bid Tab B (Port)'!J24 -> #REF! | L25: ='Bid Tab A (FAA)'!L141+'Bid Tab B (Port)'!L24 -> #REF! | N25: ='Bid Tab A (FAA)'!N141+'Bid Tab B (Port)'!N24 -> #REF! | P25: =P24+'Bid Tab A (FAA)'!P141 -> #REF! | R25: ='Bid Tab A (FAA)'!R141+'Bid Tab B (Port)'!R24 -> #REF!

Sheet Summary
A1: ='Bid Item List B (Port)'!$A$15 -> PORTLAND INTERNATIONAL AIRPORT
A2: ='Bid Item List B (Port)'!$A$16 -> TAXIWAY B CENTER AND EXITS REHABILITATION
A3: ='Bid Item List B (Port)'!$A$17 -> 0
A4: ='Bid Tab B (Port)'!$A$4 -> EAN 2015D147
A5: ='Bid Tab B (Port)'!$A$5 -> Solicitation No. 2016-6920
A6: =TODAY() -> 42754
A7: Bidder | B7: Total Price
A8: =Contractor4 -> Kodiak Pacific Construction | B8: $16,474,320.00*^ | D8: ='Bid Tab B (Port)'!L25 -> #REF!
A9: =Contractor2 -> K&E Excavating, Inc. | B9: ='Bid Tab B (Port)'!H25 -> #REF!
A10: =Contractor3 -> Kerr Contractors Oregon, Inc. | B10: ='Bid Tab B (Port)'!J25 -> #REF!
A11: =Contractor5 -> Nutter Corp. | B11: ='Bid Tab B (Port)'!N25 -> #REF!
A12: =Contractor1 -> Goodfella Bros., Inc. | B12: ='Bid Tab B (Port)'!F25 -> #REF!
A13: =Contractor6 -> Wildish Standard Paving Co. | B13: $19,685,462.00* | D13: ='Bid Tab B (Port)'!P25 -> #REF!
A14: =EngineerEstimate -> Engineer's Estimate | B14: ='Bid Tab B (Port)'!R25 -> #REF!
A15: *Corrected bid total
A16: ^Non-responsive
